Workbook

Sheet CSE
A1: S.no | B1: Roll Number | C1: Name | D1: 6M Internship | E1: First Company Placed | F1: Package | G1: Second Company Placed | H1: Package | I1: Third Company Placed | J1: Package | K1: Fourth Company Placed | L1: Package | M1: Fifth Company Placed | N1: Package | O1: Sixth Company Placed | P1: Package | Q1: Seventh Company Placed | R1: Package | S1: Eighth Company Placed | T1: Package | U1: Ninth Company Placed | V1: Package
A2: 1 | B2: ='CSE1'!B2 -> 160118733001 | C2: ='CSE1'!C2 -> Chaitanya Changala | D2: ='CSE1'!D2 -> YES | E2: ='CSE1'!E2 -> GAP | F2: ='CSE1'!F2 -> 9.08 LPA | G2: ='CSE1'!G2 -> Cognizant GenC Elevate | H2: ='CSE1'!H2 -> 4 LPA | I2: ='CSE1'!I2 | ... U2: ='CSE1'!U2
A3: 2 | B3: ='CSE1'!B3 -> 160118733002 | C3: ='CSE1'!C3 -> Begari Deepthi | D3: ='CSE1'!D3 | E3: ='CSE1'!E3 -> Accenture (ASE) | F3: ='CSE1'!F3 -> 4.5 LPA | G3: ='CSE1'!G3 -> Modak Analytics | H3: ='CSE1'!H3 -> 6 LPA | I3: ='CSE1'!I3 -> Merilytics | ... U3: ='CSE1'!U3
A4: 3 | B4: ='CSE1'!B4 -> 160118733003 | C4: ='CSE1'!C4 -> Dharani Dadamoni | D4: ='CSE1'!D4 | E4: ='CSE1'!E4 -> LTI (Level 1) | F4: ='CSE1'!F4 -> 5 LPA | G4: ='CSE1'!G4 -> Wipro | H4: ='CSE1'!H4 -> 3.5 LPA | I4: ='CSE1'!I4 | ... U4: ='CSE1'!U4
A5: 4 | B5: ='CSE1'!B5 -> 160118733004 | C5: ='CSE1'!C5 -> Dharani V | D5: ='CSE1'!D5 -> YES | E5: ='CSE1'!E5 -> JPMC (PPO) | F5: ='CSE1'!F5 -> 14 LPA | G5: ='CSE1'!G5 | H5: ='CSE1'!H5 | I5: ='CSE1'!I5 | ... U5: ='CSE1'!U5
A6: 5 | B6: ='CSE1'!B6 -> 160118733005 | C6: ='CSE1'!C6 -> Vundavalli Gayathri Kanthi Lahari | D6: ='CSE1'!D6 -> YES | E6: ='CSE1'!E6 -> JPMC | F6: ='CSE1'!F6 -> 14 LPA | G6: ='CSE1'!G6 -> Infosys (SE) | H6: ='CSE1'!H6 -> 3.6 LPA | I6: ='CSE1'!I6 | ... U6: ='CSE1'!U6
A7: 6 | B7: ='CSE1'!B7 -> 160118733006 | C7: ='CSE1'!C7 -> Kokkirala Gouri Sirisha | D7: ='CSE1'!D7 -> YES | E7: ='CSE1'!E7 -> Cognizant GenC | F7: ='CSE1'!F7 -> 4 LPA | G7: ='CSE1'!G7 -> Next Education | H7: ='CSE1'!H7 -> 6 LPA | I7: ='CSE1'!I7 -> MTX | ... U7: ='CSE1'!U7
A8: 7 | B8: ='CSE1'!B8 -> 160118733007 | C8: ='CSE1'!C8 -> G. Greeshma | D8: ='CSE1'!D8 -> YES | E8: ='CSE1'!E8 -> Micron (MFG) | F8: ='CSE1'!F8 -> 8.1 LPA | G8: ='CSE1'!G8 | H8: ='CSE1'!H8 | I8: ='CSE1'!I8 | ... U8: ='CSE1'!U8
A9: 8 | B9: ='CSE1'!B9 -> 160118733008 | C9: ='CSE1'!C9 -> Lavanya Gandla | D9: ='CSE1'!D9 -> YES | E9: ='CSE1'!E9 -> LTI (Level 1) | F9: ='CSE1'!F9 -> 5 LPA | G9: ='CSE1'!G9 -> Wipro | H9: ='CSE1'!H9 -> 3.5 LPA | I9: ='CSE1'!I9 -> Next Education (Internship) | ... U9: ='CSE1'!U9
A10: 9 | B10: ='CSE1'!B10 -> 160118733009 | C10: ='CSE1'!C10 -> RATHOD MAHESHWARI | D10: ='CSE1'!D10 | E10: ='CSE1'!E10 | F10: ='CSE1'!F10 | G10: ='CSE1'!G10 | H10: ='CSE1'!H10 | I10: ='CSE1'!I10 | ... U10: ='CSE1'!U10
A11: 10 | B11: ='CSE1'!B11 -> 160118733010 | C11: ='CSE1'!C11 -> Katta Naga Shivani Reddy | D11: ='CSE1'!D11 -> YES | E11: ='CSE1'!E11 -> JPMC | F11: ='CSE1'!F11 -> 14 LPA | G11: ='CSE1'!G11 | H11: ='CSE1'!H11 | I11: ='CSE1'!I11 | ... U11: ='CSE1'!U11
A12: 11 | B12: ='CSE1'!B12 -> 160118733011 | C12: ='CSE1'!C12 -> Sai Annanya Sree Vedala | D12: ='CSE1'!D12 -> YES | E12: ='CSE1'!E12 -> JPMC (PPO) | F12: ='CSE1'!F12 -> 14 LPA | G12: ='CSE1'!G12 | H12: ='CSE1'!H12 | I12: ='CSE1'!I12 | ... U12: ='CSE1'!U12
A13: 12 | B13: ='CSE1'!B13 -> 160118733012 | C13: ='CSE1'!C13 -> Sai Prathyusha G | D13: ='CSE1'!D13 -> YES | E13: ='CSE1'!E13 -> JPMC (PPO) | F13: ='CSE1'!F13 -> 14 LPA | G13: ='CSE1'!G13 -> F5 Inc | H13: ='CSE1'!H13 -> 23 LPA | I13: ='CSE1'!I13 | ... U13: ='CSE1'!U13
A14: 13 | B14: ='CSE1'!B14 -> 160118733013 | C14: ='CSE1'!C14 -> Sai sanjana reddy Vatte | D14: ='CSE1'!D14 | E14: ='CSE1'!E14 | F14: ='CSE1'!F14 | G14: ='CSE1'!G14 | H14: ='CSE1'!H14 | I14: ='CSE1'!I14 | ... U14: ='CSE1'!U14
A15: 14 | B15: ='CSE1'!B15 -> 160118733014 | C15: ='CSE1'!C15 -> Sirnam Sanjana | D15: ='CSE1'!D15 -> YES | E15: ='CSE1'!E15 -> JPMC | F15: ='CSE1'!F15 -> 14 LPA | G15: ='CSE1'!G15 -> Deloitte (Tax PPO) | H15: ='CSE1'!H15 -> 7.6 LPA | I15: ='CSE1'!I15 -> F5 Inc | J15: 23 LPA | K15: ='CSE1'!K15 | L15: ='CSE1'!L15 | M15: ='CSE1'!M15 | N15: ='CSE1'!N15 | O15: ='CSE1'!O15 | P15: ='CSE1'!P15 | Q15: ='CSE1'!Q15 | R15: ='CSE1'!R15 | ... U15: ='CSE1'!U15
A16: 15 | B16: ='CSE1'!B16 -> 160118733015 | C16: ='CSE1'!C16 -> Sanjana Varma Mudunuri | D16: ='CSE1'!D16 | E16: ='CSE1'!E16 | F16: ='CSE1'!F16 | G16: ='CSE1'!G16 | H16: ='CSE1'!H16 | I16: ='CSE1'!I16 | ... U16: ='CSE1'!U16
A17: 16 | B17: ='CSE1'!B17 -> 160118733016 | C17: ='CSE1'!C17 -> Sathvika Balabhadra | D17: ='CSE1'!D17 -> YES | E17: ='CSE1'!E17 -> Accenture (ASE) | F17: ='CSE1'!F17 -> 4.5 LPA | G17: ='CSE1'!G17 -> Cognizant GenC | H17: ='CSE1'!H17 -> 4 LPA | I17: ='CSE1'!I17 | ... U17: ='CSE1'!U17
A18: 17 | B18: ='CSE1'!B18 -> 160118733017 | C18: ='CSE1'!C18 -> Sheetal rao | D18: ='CSE1'!D18 | E18: ='CSE1'!E18 -> DBS | F18: ='CSE1'!F18 -> 8.5 LPA | G18: ='CSE1'!G18 | H18: ='CSE1'!H18 | I18: ='CSE1'!I18 | ... U18: ='CSE1'!U18
A19: 18 | B19: ='CSE1'!B19 -> 160118733018 | C19: ='CSE1'!C19 -> Shreya Maramreddy | D19: ='CSE1'!D19 | E19: ='CSE1'!E19 | F19: ='CSE1'!F19 | G19: ='CSE1'!G19 | H19: ='CSE1'!H19 | I19: ='CSE1'!I19 | ... U19: ='CSE1'!U19
A20: 19 | B20: ='CSE1'!B20 -> 160118733019 | C20: ='CSE1'!C20 -> Sudeeshna Deva | D20: ='CSE1'!D20 -> YES | E20: ='CSE1'!E20 -> LTI (Level 3) | F20: ='CSE1'!F20 -> 8 LPA | G20: ='CSE1'!G20 -> Accenture (ASE) | H20: ='CSE1'!H20 -> 4.5 LPA | I20: ='CSE1'!I20 -> Cognizant GenC Elevate | ... U20: ='CSE1'!U20
A21: 20 | B21: ='CSE1'!B21 -> 160118733020 | C21: ='CSE1'!C21 -> Mankala Sukritha | D21: ='CSE1'!D21 | E21: ='CSE1'!E21 -> SalesForce | F21: ='CSE1'!F21 -> 19.65 LPA | G21: ='CSE1'!G21 | H21: ='CSE1'!H21 | I21: ='CSE1'!I21 | ... U21: ='CSE1'!U21
A22: 21 | B22: ='CSE1'!B22 -> 160118733021 | C22: ='CSE1'!C22 -> Dara Supriya | D22: ='CSE1'!D22 | E22: ='CSE1'!E22 -> Deloitte (Consulting) | F22: ='CSE1'!F22 -> 7.6 LPA | G22: ='CSE1'!G22 | H22: ='CSE1'!H22 | I22: ='CSE1'!I22 | ... U22: ='CSE1'!U22
A23: 22 | B23: ='CSE1'!B23 -> 160118733022 | C23: ='CSE1'!C23 -> Supriya Kaluri | D23: ='CSE1'!D23 -> YES | E23: ='CSE1'!E23 -> LTI (Level 2) | F23: ='CSE1'!F23 -> 6.5 LPA | G23: ='CSE1'!G23 -> Accenture (ASE) | H23: ='CSE1'!H23 -> 4.5 LPA | I23: ='CSE1'!I23 -> Amazon (Internship) | ... U23: ='CSE1'!U23
A24: 23 | B24: ='CSE1'!B24 -> 160118733023 | C24: ='CSE1'!C24 -> Sushma M | D24: ='CSE1'!D24 | E24: ='CSE1'!E24 -> Deloitte (Consulting) | F24: ='CSE1'!F24 -> 7.6 LPA | G24: ='CSE1'!G24 | H24: ='CSE1'!H24 | I24: ='CSE1'!I24 | ... U24: ='CSE1'!U24
A25: 24 | B25: ='CSE1'!B25 -> 160118733024 | C25: ='CSE1'!C25 -> Mohammed Abdul Muhaymin | D25: ='CSE1'!D25 | E25: ='CSE1'!E25 -> Deloitte (Consulting) | F25: ='CSE1'!F25 -> 7.6 LPA | G25: ='CSE1'!G25 | H25: ='CSE1'!H25 | I25: ='CSE1'!I25 | ... U25: ='CSE1'!U25
A26: 25 | B26: ='CSE1'!B26 -> 160118733025 | C26: ='CSE1'!C26 -> Muzzammil Ahmed | D26: ='CSE1'!D26 -> YES | E26: ='CSE1'!E26 -> Cognizant GenC Next | F26: ='CSE1'!F26 -> 6.75 LPA | G26: ='CSE1'!G26 -> Barclays | H26: ='CSE1'!H26 -> 12.73 LPA | I26: ='CSE1'!I26 -> Infosys (SE) | ... U26: ='CSE1'!U26
A27: 26 | B27: ='CSE1'!B27 -> 160118733026 | C27: ='CSE1'!C27 -> Akshay Kumar Malathkar | D27: ='CSE1'!D27 -> YES | E27: ='CSE1'!E27 -> Accelerize 360 | F27: ='CSE1'!F27 -> 7 LPA | G27: ='CSE1'!G27 -> Infosys (SE) | H27: ='CSE1'!H27 -> 3.6 LPA | I27: ='CSE1'!I27 -> VISA | ... U27: ='CSE1'!U27
... A74: 73 | B74: ='CSE1'!B74 | C74: ='CSE1'!C74 | D74: ='CSE1'!D74 | E74: ='CSE1'!E74 | F74: ='CSE1'!F74 | G74: ='CSE1'!G74 | H74: ='CSE1'!H74 | I74: ='CSE1'!I74 | ... U74: ='CSE1'!U74
A75: 74 | B75: ='CSE2'!B2 -> 160118733061 | C75: ='CSE2'!C2 -> Akhila Patlolla | D75: ='CSE2'!D2 | E75: ='CSE2'!E2 -> Wipro | F75: ='CSE2'!F2 -> 3.5 LPA | G75: ='CSE2'!G2 -> Mu Sigma | H75: ='CSE2'!H2 -> 3.5 LPA | I75: ='CSE2'!I2 | ... U75: ='CSE2'!U2
A76: 75 | B76: ='CSE2'!B3 -> 160118733062 | C76: ='CSE2'!C3 -> Bhavishya Agarwal | D76: ='CSE2'!D3 -> YES | E76: ='CSE2'!E3 -> SalesForce | F76: ='CSE2'!F3 -> 19.65 LPA | G76: ='CSE2'!G3 -> Infosys (SE) | H76: ='CSE2'!H3 -> 3.6 LPA | I76: ='CSE2'!I3 -> Caspian Debt (Internship) | ... U76: ='CSE2'!U3
A77: 76 | B77: ='CSE2'!B4 -> 160118733063 | C77: ='CSE2'!C4 -> Harshitha Dendeti | D77: ='CSE2'!D4 -> YES | E77: ='CSE2'!E4 -> Cognizant GenC Elevate | F77: ='CSE2'!F4 -> 4 LPA | G77: ='CSE2'!G4 | H77: ='CSE2'!H4 | I77: ='CSE2'!I4 | ... U77: ='CSE2'!U4
A78: 77 | B78: ='CSE2'!B5 -> 160118733064 | C78: ='CSE2'!C5 -> Jahnavi Jonnalagadda | D78: ='CSE2'!D5 | E78: ='CSE2'!E5 -> Advance Auto Parts (PPO) | F78: ='CSE2'!F5 -> 9 LPA | G78: ='CSE2'!G5 -> F5 Inc | H78: ='CSE2'!H5 -> 23 LPA | I78: ='CSE2'!I5 | ... U78: ='CSE2'!U5
A79: 78 | B79: ='CSE2'!B6 -> 160118733065 | C79: ='CSE2'!C6 -> Keerthi Boya | D79: ='CSE2'!D6 -> YES | E79: ='CSE2'!E6 -> Accenture (ASE) | F79: ='CSE2'!F6 -> 4.5 LPA | G79: ='CSE2'!G6 -> Wipro | H79: ='CSE2'!H6 -> 3.5 LPA | I79: ='CSE2'!I6 -> Collins Aerospace (Internship) | ... L79: ='CSE2'!L6 -> 5.7 LPA | M79: Loyalty Juggernaut Inc | N79: 7LPA | O79: ='CSE2'!O6 -> Head Digital Works | P79: ='CSE2'!P6 -> 12 LPA | Q79: ='CSE2'!Q6 | R79: ='CSE2'!R6 | S79: ='CSE2'!S6 | T79: ='CSE2'!T6 | U79: ='CSE2'!U6
A80: 79 | B80: ='CSE2'!B7 -> 160118733066 | C80: ='CSE2'!C7 -> Kini Sanjula Dasari | D80: ='CSE2'!D7 | E80: ='CSE2'!E7 -> Deloitte (Consulting) | F80: ='CSE2'!F7 -> 7.6 LPA | G80: ='CSE2'!G7 -> Barclays | H80: ='CSE2'!H7 -> 12.73 LPA | I80: ='CSE2'!I7 | ... U80: ='CSE2'!U7
A81: 80 | B81: ='CSE2'!B8 -> 160118733067 | C81: ='CSE2'!C8 -> Komali Beeram | D81: ='CSE2'!D8 -> YES | E81: ='CSE2'!E8 -> Accelerize 360 | F81: ='CSE2'!F8 -> 7 LPA | G81: ='CSE2'!G8 -> Cognizant GenC Next | H81: ='CSE2'!H8 -> 6.75 LPA | I81: ='CSE2'!I8 -> GE Appliances (Internship) | ... U81: ='CSE2'!U8
A82: 81 | B82: ='CSE2'!B9 -> 160118733068 | C82: ='CSE2'!C9 -> Manasa Motepalli | D82: ='CSE2'!D9 -> YES | E82: ='CSE2'!E9 -> Accenture (ASE) | F82: ='CSE2'!F9 -> 4.5 LPA | G82: ='CSE2'!G9 -> Cognizant GenC | H82: ='CSE2'!H9 -> 4 LPA | I82: ='CSE2'!I9 -> Capgemini (Analyst) | ... U82: ='CSE2'!U9
A83: 82 | B83: ='CSE2'!B10 -> 160118733069 | C83: ='CSE2'!C10 -> Rizmi Nawaz Sowdhagar | D83: ='CSE2'!D10 | E83: ='CSE2'!E10 -> Wipro | F83: ='CSE2'!F10 -> 3.5 LPA | G83: ='CSE2'!G10 -> HCL | H83: ='CSE2'!H10 -> 4.5 LPA | I83: ='CSE2'!I10 | ... U83: ='CSE2'!U10
A84: 83 | B84: ='CSE2'!B11 -> 160118733070 | C84: ='CSE2'!C11 -> Neha Bhupathi | D84: ='CSE2'!D11 -> YES | E84: ='CSE2'!E11 -> Collins Aerospace (Internship) | F84: ='CSE2'!F11 -> 15k | G84: ='CSE2'!G11 | H84: ='CSE2'!H11 | I84: ='CSE2'!I11 | ... U84: ='CSE2'!U11
A85: 84 | B85: ='CSE2'!B12 -> 160118733071 | C85: ='CSE2'!C12 -> Nishitha Garlapati | D85: ='CSE2'!D12 -> YES | E85: ='CSE2'!E12 -> JPMC (PPO) | F85: ='CSE2'!F12 -> 14 LPA | G85: ='CSE2'!G12 | H85: ='CSE2'!H12 | I85: ='CSE2'!I12 | ... U85: ='CSE2'!U12
A86: 85 | B86: ='CSE2'!B13 -> 160118733072 | C86: ='CSE2'!C13 -> Niveditha Kalva | D86: ='CSE2'!D13 -> YES | E86: ='CSE2'!E13 -> Micron (IT Operations) | F86: ='CSE2'!F13 -> 8.1 LPA | G86: ='CSE2'!G13 | H86: ='CSE2'!H13 | I86: ='CSE2'!I13 | ... U86: ='CSE2'!U13
...

Sheet CSE1
A1: S. No | B1: Roll Number | C1: Name | D1: 6M Internship | E1: First Company Placed | F1: Package | G1: Second Company Placed | H1: Package | I1: Third Company Placed | J1: Package | K1: Fourth Company Placed | L1: Package | M1: Fifth Company Placed | N1: Package | O1: Sixth Company Placed | P1: Package | Q1: Seventh Company Placed | R1: Package | S1: Eighth Company Placed | T1: Package | U1: Ninth Company Placed | V1: Package | W1: Highest Package | X1: Eligibility
A2: 1 | B2: 160118733001 | C2: Chaitanya Changala | D2: YES | E2: GAP | F2: 9.08 LPA | G2: Cognizant GenC Elevate | H2: 4 LPA | W2: =IFERROR(__xludf.DUMMYFUNCTION("MAX(VALUE(IF(REGEXMATCH($F2, "" ""), LEFT($F2, (FIND("" "", $F2, 1) - 1)), 0)), VALUE(IF(REGEXMATCH($H2, "" ""), LEFT($H2, (FIND("" "", $H2, 1) - 1)), 0)), VALUE(IF(REGEXMATCH($J2, "" ""), LEFT($J2, (FIND("" "", $J2, 1) - 1)), 0)), VALUE(IF(REGEXMATCH($L2"&", "" ""), LEFT($L2, (FIND("" "", $L2, 1) - 1)), 0)), VALUE(IF(REGEXMATCH($N2, "" ""), LEFT($N2, (FIND("" "", $N2, 1) - 1)), 0)), VALUE(IF(REGEXMATCH($P2, "" ""), LEFT($P2, (FIND("" "", $P2, 1) - 1)), 0)), VALUE(IF(REGEXMATCH($R2, "" ""), LEFT($R2, (FIND("&""" "", $R2, 1) - 1)), 0)), VALUE(IF(REGEXMATCH($T2, "" ""), LEFT($T2, (FIND("" "", $T2, 1) - 1)), 0)), VALUE(IF(REGEXMATCH($V2, "" ""), LEFT($V2, (FIND("" "", $V2, 1) - 1)), 0)))"),9.08) -> 9.08 | X2: =$W2*1.25 -> 11.35
A3: 2 | B3: 160118733002 | C3: Begari Deepthi | E3: Accenture (ASE) | F3: 4.5 LPA | G3: Modak Analytics | H3: 6 LPA | I3: Merilytics | J3: 6.5 LPA | K3: Wipro | L3: 3.5 LPA | M3: DBS | N3: 8.5 LPA | W3: =IFERROR(__xludf.DUMMYFUNCTION("MAX(VALUE(IF(REGEXMATCH($F3, "" ""), LEFT($F3, (FIND("" "", $F3, 1) - 1)), 0)), VALUE(IF(REGEXMATCH($H3, "" ""), LEFT($H3, (FIND("" "", $H3, 1) - 1)), 0)), VALUE(IF(REGEXMATCH($J3, "" ""), LEFT($J3, (FIND("" "", $J3, 1) - 1)), 0)), VALUE(IF(REGEXMATCH($L3"&", "" ""), LEFT($L3, (FIND("" "", $L3, 1) - 1)), 0)), VALUE(IF(REGEXMATCH($N3, "" ""), LEFT($N3, (FIND("" "", $N3, 1) - 1)), 0)), VALUE(IF(REGEXMATCH($P3, "" ""), LEFT($P3, (FIND("" "", $P3, 1) - 1)), 0)), VALUE(IF(REGEXMATCH($R3, "" ""), LEFT($R3, (FIND("&""" "", $R3, 1) - 1)), 0)), VALUE(IF(REGEXMATCH($T3, "" ""), LEFT($T3, (FIND("" "", $T3, 1) - 1)), 0)), VALUE(IF(REGEXMATCH($V3, "" ""), LEFT($V3, (FIND("" "", $V3, 1) - 1)), 0)))"),8.5) -> 8.5 | X3: =$W3*1.25 -> 10.625
A4: 3 | B4: 160118733003 | C4: Dharani Dadamoni | E4: LTI (Level 1) | F4: 5 LPA | G4: Wipro | H4: 3.5 LPA | W4: =IFERROR(__xludf.DUMMYFUNCTION("MAX(VALUE(IF(REGEXMATCH($F4, "" ""), LEFT($F4, (FIND("" "", $F4, 1) - 1)), 0)), VALUE(IF(REGEXMATCH($H4, "" ""), LEFT($H4, (FIND("" "", $H4, 1) - 1)), 0)), VALUE(IF(REGEXMATCH($J4, "" ""), LEFT($J4, (FIND("" "", $J4, 1) - 1)), 0)), VALUE(IF(REGEXMATCH($L4"&", "" ""), LEFT($L4, (FIND("" "", $L4, 1) - 1)), 0)), VALUE(IF(REGEXMATCH($N4, "" ""), LEFT($N4, (FIND("" "", $N4, 1) - 1)), 0)), VALUE(IF(REGEXMATCH($P4, "" ""), LEFT($P4, (FIND("" "", $P4, 1) - 1)), 0)), VALUE(IF(REGEXMATCH($R4, "" ""), LEFT($R4, (FIND("&""" "", $R4, 1) - 1)), 0)), VALUE(IF(REGEXMATCH($T4, "" ""), LEFT($T4, (FIND("" "", $T4, 1) - 1)), 0)), VALUE(IF(REGEXMATCH($V4, "" ""), LEFT($V4, (FIND("" "", $V4, 1) - 1)), 0)))"),5.0) -> 5 | X4: =$W4*1.25 -> 6.25
A5: 4 | B5: 160118733004 | C5: Dharani V | D5: YES | E5: JPMC (PPO) | F5: 14 LPA | W5: =IFERROR(__xludf.DUMMYFUNCTION("MAX(VALUE(IF(REGEXMATCH($F5, "" ""), LEFT($F5, (FIND("" "", $F5, 1) - 1)), 0)), VALUE(IF(REGEXMATCH($H5, "" ""), LEFT($H5, (FIND("" "", $H5, 1) - 1)), 0)), VALUE(IF(REGEXMATCH($J5, "" ""), LEFT($J5, (FIND("" "", $J5, 1) - 1)), 0)), VALUE(IF(REGEXMATCH($L5"&", "" ""), LEFT($L5, (FIND("" "", $L5, 1) - 1)), 0)), VALUE(IF(REGEXMATCH($N5, "" ""), LEFT($N5, (FIND("" "", $N5, 1) - 1)), 0)), VALUE(IF(REGEXMATCH($P5, "" ""), LEFT($P5, (FIND("" "", $P5, 1) - 1)), 0)), VALUE(IF(REGEXMATCH($R5, "" ""), LEFT($R5, (FIND("&""" "", $R5, 1) - 1)), 0)), VALUE(IF(REGEXMATCH($T5, "" ""), LEFT($T5, (FIND("" "", $T5, 1) - 1)), 0)), VALUE(IF(REGEXMATCH($V5, "" ""), LEFT($V5, (FIND("" "", $V5, 1) - 1)), 0)))"),14.0) -> 14 | X5: =$W5*1.25 -> 17.5
A6: 5 | B6: 160118733005 | C6: Vundavalli Gayathri Kanthi Lahari | D6: YES | E6: JPMC | F6: 14 LPA | G6: Infosys (SE) | H6: 3.6 LPA | W6: =IFERROR(__xludf.DUMMYFUNCTION("MAX(VALUE(IF(REGEXMATCH($F6, "" ""), LEFT($F6, (FIND("" "", $F6, 1) - 1)), 0)), VALUE(IF(REGEXMATCH($H6, "" ""), LEFT($H6, (FIND("" "", $H6, 1) - 1)), 0)), VALUE(IF(REGEXMATCH($J6, "" ""), LEFT($J6, (FIND("" "", $J6, 1) - 1)), 0)), VALUE(IF(REGEXMATCH($L6"&", "" ""), LEFT($L6, (FIND("" "", $L6, 1) - 1)), 0)), VALUE(IF(REGEXMATCH($N6, "" ""), LEFT($N6, (FIND("" "", $N6, 1) - 1)), 0)), VALUE(IF(REGEXMATCH($P6, "" ""), LEFT($P6, (FIND("" "", $P6, 1) - 1)), 0)), VALUE(IF(REGEXMATCH($R6, "" ""), LEFT($R6, (FIND("&""" "", $R6, 1) - 1)), 0)), VALUE(IF(REGEXMATCH($T6, "" ""), LEFT($T6, (FIND("" "", $T6, 1) - 1)), 0)), VALUE(IF(REGEXMATCH($V6, "" ""), LEFT($V6, (FIND("" "", $V6, 1) - 1)), 0)))"),14.0) -> 14 | X6: =$W6*1.25 -> 17.5
A7: 6 | B7: 160118733006 | C7: Kokkirala Gouri Sirisha | D7: YES | E7: Cognizant GenC | F7: 4 LPA | G7: Next Education | H7: 6 LPA | I7: MTX | J7: 10.4 LPA | W7: =IFERROR(__xludf.DUMMYFUNCTION("MAX(VALUE(IF(REGEXMATCH($F7, "" ""), LEFT($F7, (FIND("" "", $F7, 1) - 1)), 0)), VALUE(IF(REGEXMATCH($H7, "" ""), LEFT($H7, (FIND("" "", $H7, 1) - 1)), 0)), VALUE(IF(REGEXMATCH($J7, "" ""), LEFT($J7, (FIND("" "", $J7, 1) - 1)), 0)), VALUE(IF(REGEXMATCH($L7"&", "" ""), LEFT($L7, (FIND("" "", $L7, 1) - 1)), 0)), VALUE(IF(REGEXMATCH($N7, "" ""), LEFT($N7, (FIND("" "", $N7, 1) - 1)), 0)), VALUE(IF(REGEXMATCH($P7, "" ""), LEFT($P7, (FIND("" "", $P7, 1) - 1)), 0)), VALUE(IF(REGEXMATCH($R7, "" ""), LEFT($R7, (FIND("&""" "", $R7, 1) - 1)), 0)), VALUE(IF(REGEXMATCH($T7, "" ""), LEFT($T7, (FIND("" "", $T7, 1) - 1)), 0)), VALUE(IF(REGEXMATCH($V7, "" ""), LEFT($V7, (FIND("" "", $V7, 1) - 1)), 0)))"),10.4) -> 10.4 | X7: =$W7*1.25 -> 13
A8: 7 | B8: 160118733007 | C8: G. Greeshma | D8: YES | E8: Micron (MFG) | F8: 8.1 LPA | W8: =IFERROR(__xludf.DUMMYFUNCTION("MAX(VALUE(IF(REGEXMATCH($F8, "" ""), LEFT($F8, (FIND("" "", $F8, 1) - 1)), 0)), VALUE(IF(REGEXMATCH($H8, "" ""), LEFT($H8, (FIND("" "", $H8, 1) - 1)), 0)), VALUE(IF(REGEXMATCH($J8, "" ""), LEFT($J8, (FIND("" "", $J8, 1) - 1)), 0)), VALUE(IF(REGEXMATCH($L8"&", "" ""), LEFT($L8, (FIND("" "", $L8, 1) - 1)), 0)), VALUE(IF(REGEXMATCH($N8, "" ""), LEFT($N8, (FIND("" "", $N8, 1) - 1)), 0)), VALUE(IF(REGEXMATCH($P8, "" ""), LEFT($P8, (FIND("" "", $P8, 1) - 1)), 0)), VALUE(IF(REGEXMATCH($R8, "" ""), LEFT($R8, (FIND("&""" "", $R8, 1) - 1)), 0)), VALUE(IF(REGEXMATCH($T8, "" ""), LEFT($T8, (FIND("" "", $T8, 1) - 1)), 0)), VALUE(IF(REGEXMATCH($V8, "" ""), LEFT($V8, (FIND("" "", $V8, 1) - 1)), 0)))"),8.1) -> 8.1 | X8: =$W8*1.25 -> 10.125
A9: 8 | B9: 160118733008 | C9: Lavanya Gandla | D9: YES | E9: LTI (Level 1) | F9: 5 LPA | G9: Wipro | H9: 3.5 LPA | I9: Next Education (Internship) | J9: 15k | K9: GAP | L9: 9.08 LPA | W9: =IFERROR(__xludf.DUMMYFUNCTION("MAX(VALUE(IF(REGEXMATCH($F9, "" ""), LEFT($F9, (FIND("" "", $F9, 1) - 1)), 0)), VALUE(IF(REGEXMATCH($H9, "" ""), LEFT($H9, (FIND("" "", $H9, 1) - 1)), 0)), VALUE(IF(REGEXMATCH($J9, "" ""), LEFT($J9, (FIND("" "", $J9, 1) - 1)), 0)), VALUE(IF(REGEXMATCH($L9"&", "" ""), LEFT($L9, (FIND("" "", $L9, 1) - 1)), 0)), VALUE(IF(REGEXMATCH($N9, "" ""), LEFT($N9, (FIND("" "", $N9, 1) - 1)), 0)), VALUE(IF(REGEXMATCH($P9, "" ""), LEFT($P9, (FIND("" "", $P9, 1) - 1)), 0)), VALUE(IF(REGEXMATCH($R9, "" ""), LEFT($R9, (FIND("&""" "", $R9, 1) - 1)), 0)), VALUE(IF(REGEXMATCH($T9, "" ""), LEFT($T9, (FIND("" "", $T9, 1) - 1)), 0)), VALUE(IF(REGEXMATCH($V9, "" ""), LEFT($V9, (FIND("" "", $V9, 1) - 1)), 0)))"),9.08) -> 9.08 | X9: =$W9*1.25 -> 11.35
A10: 9 | B10: 160118733009 | C10: RATHOD MAHESHWARI | W10: =IFERROR(__xludf.DUMMYFUNCTION("MAX(VALUE(IF(REGEXMATCH($F10, "" ""), LEFT($F10, (FIND("" "", $F10, 1) - 1)), 0)), VALUE(IF(REGEXMATCH($H10, "" ""), LEFT($H10, (FIND("" "", $H10, 1) - 1)), 0)), VALUE(IF(REGEXMATCH($J10, "" ""), LEFT($J10, (FIND("" "", $J10, 1) - 1)), 0)), VALUE(IF(REGEX"&"MATCH($L10, "" ""), LEFT($L10, (FIND("" "", $L10, 1) - 1)), 0)), VALUE(IF(REGEXMATCH($N10, "" ""), LEFT($N10, (FIND("" "", $N10, 1) - 1)), 0)), VALUE(IF(REGEXMATCH($P10, "" ""), LEFT($P10, (FIND("" "", $P10, 1) - 1)), 0)), VALUE(IF(REGEXMATCH($R10, "" "")"&", LEFT($R10, (FIND("" "", $R10, 1) - 1)), 0)), VALUE(IF(REGEXMATCH($T10, "" ""), LEFT($T10, (FIND("" "", $T10, 1) - 1)), 0)), VALUE(IF(REGEXMATCH($V10, "" ""), LEFT($V10, (FIND("" "", $V10, 1) - 1)), 0)))"),0.0) -> 0 | X10: =$W10*1.25 -> 0
A11: 10 | B11: 160118733010 | C11: Katta Naga Shivani Reddy | D11: YES | E11: JPMC | F11: 14 LPA | W11: =IFERROR(__xludf.DUMMYFUNCTION("MAX(VALUE(IF(REGEXMATCH($F11, "" ""), LEFT($F11, (FIND("" "", $F11, 1) - 1)), 0)), VALUE(IF(REGEXMATCH($H11, "" ""), LEFT($H11, (FIND("" "", $H11, 1) - 1)), 0)), VALUE(IF(REGEXMATCH($J11, "" ""), LEFT($J11, (FIND("" "", $J11, 1) - 1)), 0)), VALUE(IF(REGEX"&"MATCH($L11, "" ""), LEFT($L11, (FIND("" "", $L11, 1) - 1)), 0)), VALUE(IF(REGEXMATCH($N11, "" ""), LEFT($N11, (FIND("" "", $N11, 1) - 1)), 0)), VALUE(IF(REGEXMATCH($P11, "" ""), LEFT($P11, (FIND("" "", $P11, 1) - 1)), 0)), VALUE(IF(REGEXMATCH($R11, "" "")"&", LEFT($R11, (FIND("" "", $R11, 1) - 1)), 0)), VALUE(IF(REGEXMATCH($T11, "" ""), LEFT($T11, (FIND("" "", $T11, 1) - 1)), 0)), VALUE(IF(REGEXMATCH($V11, "" ""), LEFT($V11, (FIND("" "", $V11, 1) - 1)), 0)))"),14.0) -> 14 | X11: =$W11*1.25 -> 17.5
A12: 11 | B12: 160118733011 | C12: Sai Annanya Sree Vedala | D12: YES | E12: JPMC (PPO) | F12: 14 LPA | W12: =IFERROR(__xludf.DUMMYFUNCTION("MAX(VALUE(IF(REGEXMATCH($F12, "" ""), LEFT($F12, (FIND("" "", $F12, 1) - 1)), 0)), VALUE(IF(REGEXMATCH($H12, "" ""), LEFT($H12, (FIND("" "", $H12, 1) - 1)), 0)), VALUE(IF(REGEXMATCH($J12, "" ""), LEFT($J12, (FIND("" "", $J12, 1) - 1)), 0)), VALUE(IF(REGEX"&"MATCH($L12, "" ""), LEFT($L12, (FIND("" "", $L12, 1) - 1)), 0)), VALUE(IF(REGEXMATCH($N12, "" ""), LEFT($N12, (FIND("" "", $N12, 1) - 1)), 0)), VALUE(IF(REGEXMATCH($P12, "" ""), LEFT($P12, (FIND("" "", $P12, 1) - 1)), 0)), VALUE(IF(REGEXMATCH($R12, "" "")"&", LEFT($R12, (FIND("" "", $R12, 1) - 1)), 0)), VALUE(IF(REGEXMATCH($T12, "" ""), LEFT($T12, (FIND("" "", $T12, 1) - 1)), 0)), VALUE(IF(REGEXMATCH($V12, "" ""), LEFT($V12, (FIND("" "", $V12, 1) - 1)), 0)))"),14.0) -> 14 | X12: =$W12*1.25 -> 17.5
A13: 12 | B13: 160118733012 | C13: Sai Prathyusha G | D13: YES | E13: JPMC (PPO) | F13: 14 LPA | G13: F5 Inc | H13: 23 LPA | W13: =IFERROR(__xludf.DUMMYFUNCTION("MAX(VALUE(IF(REGEXMATCH($F13, "" ""), LEFT($F13, (FIND("" "", $F13, 1) - 1)), 0)), VALUE(IF(REGEXMATCH($H13, "" ""), LEFT($H13, (FIND("" "", $H13, 1) - 1)), 0)), VALUE(IF(REGEXMATCH($J13, "" ""), LEFT($J13, (FIND("" "", $J13, 1) - 1)), 0)), VALUE(IF(REGEX"&"MATCH($L13, "" ""), LEFT($L13, (FIND("" "", $L13, 1) - 1)), 0)), VALUE(IF(REGEXMATCH($N13, "" ""), LEFT($N13, (FIND("" "", $N13, 1) - 1)), 0)), VALUE(IF(REGEXMATCH($P13, "" ""), LEFT($P13, (FIND("" "", $P13, 1) - 1)), 0)), VALUE(IF(REGEXMATCH($R13, "" "")"&", LEFT($R13, (FIND("" "", $R13, 1) - 1)), 0)), VALUE(IF(REGEXMATCH($T13, "" ""), LEFT($T13, (FIND("" "", $T13, 1) - 1)), 0)), VALUE(IF(REGEXMATCH($V13, "" ""), LEFT($V13, (FIND("" "", $V13, 1) - 1)), 0)))"),23.0) -> 23 | X13: =$W13*1.25 -> 28.75
A14: 13 | B14: 160118733013 | C14: Sai sanjana reddy Vatte | W14: =IFERROR(__xludf.DUMMYFUNCTION("MAX(VALUE(IF(REGEXMATCH($F14, "" ""), LEFT($F14, (FIND("" "", $F14, 1) - 1)), 0)), VALUE(IF(REGEXMATCH($H14, "" ""), LEFT($H14, (FIND("" "", $H14, 1) - 1)), 0)), VALUE(IF(REGEXMATCH($J14, "" ""), LEFT($J14, (FIND("" "", $J14, 1) - 1)), 0)), VALUE(IF(REGEX"&"MATCH($L14, "" ""), LEFT($L14, (FIND("" "", $L14, 1) - 1)), 0)), VALUE(IF(REGEXMATCH($N14, "" ""), LEFT($N14, (FIND("" "", $N14, 1) - 1)), 0)), VALUE(IF(REGEXMATCH($P14, "" ""), LEFT($P14, (FIND("" "", $P14, 1) - 1)), 0)), VALUE(IF(REGEXMATCH($R14, "" "")"&", LEFT($R14, (FIND("" "", $R14, 1) - 1)), 0)), VALUE(IF(REGEXMATCH($T14, "" ""), LEFT($T14, (FIND("" "", $T14, 1) - 1)), 0)), VALUE(IF(REGEXMATCH($V14, "" ""), LEFT($V14, (FIND("" "", $V14, 1) - 1)), 0)))"),0.0) -> 0 | X14: =$W14*1.25 -> 0
A15: 14 | B15: 160118733014 | C15: Sirnam Sanjana | D15: YES | E15: JPMC | F15: 14 LPA | G15: Deloitte (Tax PPO) | H15: 7.6 LPA | I15: F5 Inc | J15: 23 LPA | W15: =IFERROR(__xludf.DUMMYFUNCTION("MAX(VALUE(IF(REGEXMATCH($F15, "" ""), LEFT($F15, (FIND("" "", $F15, 1) - 1)), 0)), VALUE(IF(REGEXMATCH($H15, "" ""), LEFT($H15, (FIND("" "", $H15, 1) - 1)), 0)), VALUE(IF(REGEXMATCH($J15, "" ""), LEFT($J15, (FIND("" "", $J15, 1) - 1)), 0)), VALUE(IF(REGEX"&"MATCH($L15, "" ""), LEFT($L15, (FIND("" "", $L15, 1) - 1)), 0)), VALUE(IF(REGEXMATCH($N15, "" ""), LEFT($N15, (FIND("" "", $N15, 1) - 1)), 0)), VALUE(IF(REGEXMATCH($P15, "" ""), LEFT($P15, (FIND("" "", $P15, 1) - 1)), 0)), VALUE(IF(REGEXMATCH($R15, "" "")"&", LEFT($R15, (FIND("" "", $R15, 1) - 1)), 0)), VALUE(IF(REGEXMATCH($T15, "" ""), LEFT($T15, (FIND("" "", $T15, 1) - 1)), 0)), VALUE(IF(REGEXMATCH($V15, "" ""), LEFT($V15, (FIND("" "", $V15, 1) - 1)), 0)))"),23.0) -> 23 | X15: =$W15*1.25 -> 28.75
A16: 15 | B16: 160118733015 | C16: Sanjana Varma Mudunuri | W16: =IFERROR(__xludf.DUMMYFUNCTION("MAX(VALUE(IF(REGEXMATCH($F16, "" ""), LEFT($F16, (FIND("" "", $F16, 1) - 1)), 0)), VALUE(IF(REGEXMATCH($H16, "" ""), LEFT($H16, (FIND("" "", $H16, 1) - 1)), 0)), VALUE(IF(REGEXMATCH($J16, "" ""), LEFT($J16, (FIND("" "", $J16, 1) - 1)), 0)), VALUE(IF(REGEX"&"MATCH($L16, "" ""), LEFT($L16, (FIND("" "", $L16, 1) - 1)), 0)), VALUE(IF(REGEXMATCH($N16, "" ""), LEFT($N16, (FIND("" "", $N16, 1) - 1)), 0)), VALUE(IF(REGEXMATCH($P16, "" ""), LEFT($P16, (FIND("" "", $P16, 1) - 1)), 0)), VALUE(IF(REGEXMATCH($R16, "" "")"&", LEFT($R16, (FIND("" "", $R16, 1) - 1)), 0)), VALUE(IF(REGEXMATCH($T16, "" ""), LEFT($T16, (FIND("" "", $T16, 1) - 1)), 0)), VALUE(IF(REGEXMATCH($V16, "" ""), LEFT($V16, (FIND("" "", $V16, 1) - 1)), 0)))"),0.0) -> 0 | X16: =$W16*1.25 -> 0
A17: 16 | B17: 160118733016 | C17: Sathvika Balabhadra | D17: YES | E17: Accenture (ASE) | F17: 4.5 LPA | G17: Cognizant GenC | H17: 4 LPA | W17: =IFERROR(__xludf.DUMMYFUNCTION("MAX(VALUE(IF(REGEXMATCH($F17, "" ""), LEFT($F17, (FIND("" "", $F17, 1) - 1)), 0)), VALUE(IF(REGEXMATCH($H17, "" ""), LEFT($H17, (FIND("" "", $H17, 1) - 1)), 0)), VALUE(IF(REGEXMATCH($J17, "" ""), LEFT($J17, (FIND("" "", $J17, 1) - 1)), 0)), VALUE(IF(REGEX"&"MATCH($L17, "" ""), LEFT($L17, (FIND("" "", $L17, 1) - 1)), 0)), VALUE(IF(REGEXMATCH($N17, "" ""), LEFT($N17, (FIND("" "", $N17, 1) - 1)), 0)), VALUE(IF(REGEXMATCH($P17, "" ""), LEFT($P17, (FIND("" "", $P17, 1) - 1)), 0)), VALUE(IF(REGEXMATCH($R17, "" "")"&", LEFT($R17, (FIND("" "", $R17, 1) - 1)), 0)), VALUE(IF(REGEXMATCH($T17, "" ""), LEFT($T17, (FIND("" "", $T17, 1) - 1)), 0)), VALUE(IF(REGEXMATCH($V17, "" ""), LEFT($V17, (FIND("" "", $V17, 1) - 1)), 0)))"),4.5) -> 4.5 | X17: =$W17*1.25 -> 5.625
A18: 17 | B18: 160118733017 | C18: Sheetal rao | E18: DBS | F18: 8.5 LPA | W18: =IFERROR(__xludf.DUMMYFUNCTION("MAX(VALUE(IF(REGEXMATCH($F18, "" ""), LEFT($F18, (FIND("" "", $F18, 1) - 1)), 0)), VALUE(IF(REGEXMATCH($H18, "" ""), LEFT($H18, (FIND("" "", $H18, 1) - 1)), 0)), VALUE(IF(REGEXMATCH($J18, "" ""), LEFT($J18, (FIND("" "", $J18, 1) - 1)), 0)), VALUE(IF(REGEX"&"MATCH($L18, "" ""), LEFT($L18, (FIND("" "", $L18, 1) - 1)), 0)), VALUE(IF(REGEXMATCH($N18, "" ""), LEFT($N18, (FIND("" "", $N18, 1) - 1)), 0)), VALUE(IF(REGEXMATCH($P18, "" ""), LEFT($P18, (FIND("" "", $P18, 1) - 1)), 0)), VALUE(IF(REGEXMATCH($R18, "" "")"&", LEFT($R18, (FIND("" "", $R18, 1) - 1)), 0)), VALUE(IF(REGEXMATCH($T18, "" ""), LEFT($T18, (FIND("" "", $T18, 1) - 1)), 0)), VALUE(IF(REGEXMATCH($V18, "" ""), LEFT($V18, (FIND("" "", $V18, 1) - 1)), 0)))"),8.5) -> 8.5 | X18: =$W18*1.25 -> 10.625
A19: 18 | B19: 160118733018 | C19: Shreya Maramreddy | W19: =IFERROR(__xludf.DUMMYFUNCTION("MAX(VALUE(IF(REGEXMATCH($F19, "" ""), LEFT($F19, (FIND("" "", $F19, 1) - 1)), 0)), VALUE(IF(REGEXMATCH($H19, "" ""), LEFT($H19, (FIND("" "", $H19, 1) - 1)), 0)), VALUE(IF(REGEXMATCH($J19, "" ""), LEFT($J19, (FIND("" "", $J19, 1) - 1)), 0)), VALUE(IF(REGEX"&"MATCH($L19, "" ""), LEFT($L19, (FIND("" "", $L19, 1) - 1)), 0)), VALUE(IF(REGEXMATCH($N19, "" ""), LEFT($N19, (FIND("" "", $N19, 1) - 1)), 0)), VALUE(IF(REGEXMATCH($P19, "" ""), LEFT($P19, (FIND("" "", $P19, 1) - 1)), 0)), VALUE(IF(REGEXMATCH($R19, "" "")"&", LEFT($R19, (FIND("" "", $R19, 1) - 1)), 0)), VALUE(IF(REGEXMATCH($T19, "" ""), LEFT($T19, (FIND("" "", $T19, 1) - 1)), 0)), VALUE(IF(REGEXMATCH($V19, "" ""), LEFT($V19, (FIND("" "", $V19, 1) - 1)), 0)))"),0.0) -> 0 | X19: =$W19*1.25 -> 0
A20: 19 | B20: 160118733019 | C20: Sudeeshna Deva | D20: YES | E20: LTI (Level 3) | F20: 8 LPA | G20: Accenture (ASE) | H20: 4.5 LPA | I20: Cognizant GenC Elevate | J20: 4 LPA | K20: Amazon (Internship) | L20: 50k | M20: Samsung (job) | N20: 14.5 LPA | W20: =IFERROR(__xludf.DUMMYFUNCTION("MAX(VALUE(IF(REGEXMATCH($F20, "" ""), LEFT($F20, (FIND("" "", $F20, 1) - 1)), 0)), VALUE(IF(REGEXMATCH($H20, "" ""), LEFT($H20, (FIND("" "", $H20, 1) - 1)), 0)), VALUE(IF(REGEXMATCH($J20, "" ""), LEFT($J20, (FIND("" "", $J20, 1) - 1)), 0)), VALUE(IF(REGEX"&"MATCH($L20, "" ""), LEFT($L20, (FIND("" "", $L20, 1) - 1)), 0)), VALUE(IF(REGEXMATCH($N20, "" ""), LEFT($N20, (FIND("" "", $N20, 1) - 1)), 0)), VALUE(IF(REGEXMATCH($P20, "" ""), LEFT($P20, (FIND("" "", $P20, 1) - 1)), 0)), VALUE(IF(REGEXMATCH($R20, "" "")"&", LEFT($R20, (FIND("" "", $R20, 1) - 1)), 0)), VALUE(IF(REGEXMATCH($T20, "" ""), LEFT($T20, (FIND("" "", $T20, 1) - 1)), 0)), VALUE(IF(REGEXMATCH($V20, "" ""), LEFT($V20, (FIND("" "", $V20, 1) - 1)), 0)))"),14.5) -> 14.5 | X20: =$W20*1.25 -> 18.125
A21: 20 | B21: 160118733020 | C21: Mankala Sukritha | E21: SalesForce | F21: 19.65 LPA | W21: =IFERROR(__xludf.DUMMYFUNCTION("MAX(VALUE(IF(REGEXMATCH($F21, "" ""), LEFT($F21, (FIND("" "", $F21, 1) - 1)), 0)), VALUE(IF(REGEXMATCH($H21, "" ""), LEFT($H21, (FIND("" "", $H21, 1) - 1)), 0)), VALUE(IF(REGEXMATCH($J21, "" ""), LEFT($J21, (FIND("" "", $J21, 1) - 1)), 0)), VALUE(IF(REGEX"&"MATCH($L21, "" ""), LEFT($L21, (FIND("" "", $L21, 1) - 1)), 0)), VALUE(IF(REGEXMATCH($N21, "" ""), LEFT($N21, (FIND("" "", $N21, 1) - 1)), 0)), VALUE(IF(REGEXMATCH($P21, "" ""), LEFT($P21, (FIND("" "", $P21, 1) - 1)), 0)), VALUE(IF(REGEXMATCH($R21, "" "")"&", LEFT($R21, (FIND("" "", $R21, 1) - 1)), 0)), VALUE(IF(REGEXMATCH($T21, "" ""), LEFT($T21, (FIND("" "", $T21, 1) - 1)), 0)), VALUE(IF(REGEXMATCH($V21, "" ""), LEFT($V21, (FIND("" "", $V21, 1) - 1)), 0)))"),19.65) -> 19.65 | X21: =$W21*1.25 -> 24.5625
A22: 21 | B22: 160118733021 | C22: Dara Supriya | E22: Deloitte (Consulting) | F22: 7.6 LPA | W22: =IFERROR(__xludf.DUMMYFUNCTION("MAX(VALUE(IF(REGEXMATCH($F22, "" ""), LEFT($F22, (FIND("" "", $F22, 1) - 1)), 0)), VALUE(IF(REGEXMATCH($H22, "" ""), LEFT($H22, (FIND("" "", $H22, 1) - 1)), 0)), VALUE(IF(REGEXMATCH($J22, "" ""), LEFT($J22, (FIND("" "", $J22, 1) - 1)), 0)), VALUE(IF(REGEX"&"MATCH($L22, "" ""), LEFT($L22, (FIND("" "", $L22, 1) - 1)), 0)), VALUE(IF(REGEXMATCH($N22, "" ""), LEFT($N22, (FIND("" "", $N22, 1) - 1)), 0)), VALUE(IF(REGEXMATCH($P22, "" ""), LEFT($P22, (FIND("" "", $P22, 1) - 1)), 0)), VALUE(IF(REGEXMATCH($R22, "" "")"&", LEFT($R22, (FIND("" "", $R22, 1) - 1)), 0)), VALUE(IF(REGEXMATCH($T22, "" ""), LEFT($T22, (FIND("" "", $T22, 1) - 1)), 0)), VALUE(IF(REGEXMATCH($V22, "" ""), LEFT($V22, (FIND("" "", $V22, 1) - 1)), 0)))"),7.6) -> 7.6 | X22: =$W22*1.25 -> 9.5
A23: 22 | B23: 160118733022 | C23: Supriya Kaluri | D23: YES | E23: LTI (Level 2) | F23: 6.5 LPA | G23: Accenture (ASE) | H23: 4.5 LPA | I23: Amazon (Internship) | J23: 50k | K23: Wipro | L23: 3.5 LPA | W23: =IFERROR(__xludf.DUMMYFUNCTION("MAX(VALUE(IF(REGEXMATCH($F23, "" ""), LEFT($F23, (FIND("" "", $F23, 1) - 1)), 0)), VALUE(IF(REGEXMATCH($H23, "" ""), LEFT($H23, (FIND("" "", $H23, 1) - 1)), 0)), VALUE(IF(REGEXMATCH($J23, "" ""), LEFT($J23, (FIND("" "", $J23, 1) - 1)), 0)), VALUE(IF(REGEX"&"MATCH($L23, "" ""), LEFT($L23, (FIND("" "", $L23, 1) - 1)), 0)), VALUE(IF(REGEXMATCH($N23, "" ""), LEFT($N23, (FIND("" "", $N23, 1) - 1)), 0)), VALUE(IF(REGEXMATCH($P23, "" ""), LEFT($P23, (FIND("" "", $P23, 1) - 1)), 0)), VALUE(IF(REGEXMATCH($R23, "" "")"&", LEFT($R23, (FIND("" "", $R23, 1) - 1)), 0)), VALUE(IF(REGEXMATCH($T23, "" ""), LEFT($T23, (FIND("" "", $T23, 1) - 1)), 0)), VALUE(IF(REGEXMATCH($V23, "" ""), LEFT($V23, (FIND("" "", $V23, 1) - 1)), 0)))"),6.5) -> 6.5 | X23: =$W23*1.25 -> 8.125
A24: 23 | B24: 160118733023 | C24: Sushma M | E24: Deloitte (Consulting) | F24: 7.6 LPA | W24: =IFERROR(__xludf.DUMMYFUNCTION("MAX(VALUE(IF(REGEXMATCH($F24, "" ""), LEFT($F24, (FIND("" "", $F24, 1) - 1)), 0)), VALUE(IF(REGEXMATCH($H24, "" ""), LEFT($H24, (FIND("" "", $H24, 1) - 1)), 0)), VALUE(IF(REGEXMATCH($J24, "" ""), LEFT($J24, (FIND("" "", $J24, 1) - 1)), 0)), VALUE(IF(REGEX"&"MATCH($L24, "" ""), LEFT($L24, (FIND("" "", $L24, 1) - 1)), 0)), VALUE(IF(REGEXMATCH($N24, "" ""), LEFT($N24, (FIND("" "", $N24, 1) - 1)), 0)), VALUE(IF(REGEXMATCH($P24, "" ""), LEFT($P24, (FIND("" "", $P24, 1) - 1)), 0)), VALUE(IF(REGEXMATCH($R24, "" "")"&", LEFT($R24, (FIND("" "", $R24, 1) - 1)), 0)), VALUE(IF(REGEXMATCH($T24, "" ""), LEFT($T24, (FIND("" "", $T24, 1) - 1)), 0)), VALUE(IF(REGEXMATCH($V24, "" ""), LEFT($V24, (FIND("" "", $V24, 1) - 1)), 0)))"),7.6) -> 7.6 | X24: =$W24*1.25 -> 9.5
A25: 24 | B25: 160118733024 | C25: Mohammed Abdul Muhaymin | E25: Deloitte (Consulting) | F25: 7.6 LPA | W25: =IFERROR(__xludf.DUMMYFUNCTION("MAX(VALUE(IF(REGEXMATCH($F25, "" ""), LEFT($F25, (FIND("" "", $F25, 1) - 1)), 0)), VALUE(IF(REGEXMATCH($H25, "" ""), LEFT($H25, (FIND("" "", $H25, 1) - 1)), 0)), VALUE(IF(REGEXMATCH($J25, "" ""), LEFT($J25, (FIND("" "", $J25, 1) - 1)), 0)), VALUE(IF(REGEX"&"MATCH($L25, "" ""), LEFT($L25, (FIND("" "", $L25, 1) - 1)), 0)), VALUE(IF(REGEXMATCH($N25, "" ""), LEFT($N25, (FIND("" "", $N25, 1) - 1)), 0)), VALUE(IF(REGEXMATCH($P25, "" ""), LEFT($P25, (FIND("" "", $P25, 1) - 1)), 0)), VALUE(IF(REGEXMATCH($R25, "" "")"&", LEFT($R25, (FIND("" "", $R25, 1) - 1)), 0)), VALUE(IF(REGEXMATCH($T25, "" ""), LEFT($T25, (FIND("" "", $T25, 1) - 1)), 0)), VALUE(IF(REGEXMATCH($V25, "" ""), LEFT($V25, (FIND("" "", $V25, 1) - 1)), 0)))"),7.6) -> 7.6 | X25: =$W25*1.25 -> 9.5
A26: 25 | B26: 160118733025 | C26: Muzzammil Ahmed | D26: YES | E26: Cognizant GenC Next | F26: 6.75 LPA | G26: Barclays | H26: 12.73 LPA | I26: Infosys (SE) | J26: 3.6 LPA | W26: =IFERROR(__xludf.DUMMYFUNCTION("MAX(VALUE(IF(REGEXMATCH($F26, "" ""), LEFT($F26, (FIND("" "", $F26, 1) - 1)), 0)), VALUE(IF(REGEXMATCH($H26, "" ""), LEFT($H26, (FIND("" "", $H26, 1) - 1)), 0)), VALUE(IF(REGEXMATCH($J26, "" ""), LEFT($J26, (FIND("" "", $J26, 1) - 1)), 0)), VALUE(IF(REGEX"&"MATCH($L26, "" ""), LEFT($L26, (FIND("" "", $L26, 1) - 1)), 0)), VALUE(IF(REGEXMATCH($N26, "" ""), LEFT($N26, (FIND("" "", $N26, 1) - 1)), 0)), VALUE(IF(REGEXMATCH($P26, "" ""), LEFT($P26, (FIND("" "", $P26, 1) - 1)), 0)), VALUE(IF(REGEXMATCH($R26, "" "")"&", LEFT($R26, (FIND("" "", $R26, 1) - 1)), 0)), VALUE(IF(REGEXMATCH($T26, "" ""), LEFT($T26, (FIND("" "", $T26, 1) - 1)), 0)), VALUE(IF(REGEXMATCH($V26, "" ""), LEFT($V26, (FIND("" "", $V26, 1) - 1)), 0)))"),12.73) -> 12.73 | X26: =$W26*1.25 -> 15.9125
A27: 26 | B27: 160118733026 | C27: Akshay Kumar Malathkar | D27: YES | E27: Accelerize 360 | F27: 7 LPA | G27: Infosys (SE) | H27: 3.6 LPA | I27: VISA | J27: 22.79 LPA | W27: =IFERROR(__xludf.DUMMYFUNCTION("MAX(VALUE(IF(REGEXMATCH($F27, "" ""), LEFT($F27, (FIND("" "", $F27, 1) - 1)), 0)), VALUE(IF(REGEXMATCH($H27, "" ""), LEFT($H27, (FIND("" "", $H27, 1) - 1)), 0)), VALUE(IF(REGEXMATCH($J27, "" ""), LEFT($J27, (FIND("" "", $J27, 1) - 1)), 0)), VALUE(IF(REGEX"&"MATCH($L27, "" ""), LEFT($L27, (FIND("" "", $L27, 1) - 1)), 0)), VALUE(IF(REGEXMATCH($N27, "" ""), LEFT($N27, (FIND("" "", $N27, 1) - 1)), 0)), VALUE(IF(REGEXMATCH($P27, "" ""), LEFT($P27, (FIND("" "", $P27, 1) - 1)), 0)), VALUE(IF(REGEXMATCH($R27, "" "")"&", LEFT($R27, (FIND("" "", $R27, 1) - 1)), 0)), VALUE(IF(REGEXMATCH($T27, "" ""), LEFT($T27, (FIND("" "", $T27, 1) - 1)), 0)), VALUE(IF(REGEXMATCH($V27, "" ""), LEFT($V27, (FIND("" "", $V27, 1) - 1)), 0)))"),22.79) -> 22.79 | X27: =$W27*1.25 -> 28.4875
A28: 27 | B28: 160118733027 | C28: Charan teja sabbani | E28: Incture | F28: 7 LPA | G28: Wipro | H28: 3.5 LPA | I28: Infosys (SE) | J28: 3.6 LPA | W28: =IFERROR(__xludf.DUMMYFUNCTION("MAX(VALUE(IF(REGEXMATCH($F28, "" ""), LEFT($F28, (FIND("" "", $F28, 1) - 1)), 0)), VALUE(IF(REGEXMATCH($H28, "" ""), LEFT($H28, (FIND("" "", $H28, 1) - 1)), 0)), VALUE(IF(REGEXMATCH($J28, "" ""), LEFT($J28, (FIND("" "", $J28, 1) - 1)), 0)), VALUE(IF(REGEX"&"MATCH($L28, "" ""), LEFT($L28, (FIND("" "", $L28, 1) - 1)), 0)), VALUE(IF(REGEXMATCH($N28, "" ""), LEFT($N28, (FIND("" "", $N28, 1) - 1)), 0)), VALUE(IF(REGEXMATCH($P28, "" ""), LEFT($P28, (FIND("" "", $P28, 1) - 1)), 0)), VALUE(IF(REGEXMATCH($R28, "" "")"&", LEFT($R28, (FIND("" "", $R28, 1) - 1)), 0)), VALUE(IF(REGEXMATCH($T28, "" ""), LEFT($T28, (FIND("" "", $T28, 1) - 1)), 0)), VALUE(IF(REGEXMATCH($V28, "" ""), LEFT($V28, (FIND("" "", $V28, 1) - 1)), 0)))"),7.0) -> 7 | X28: =$W28*1.25 -> 8.75
A29: 28 | B29: 160118733028 | C29: Dhruvraj Tondanoorthy | W29: =IFERROR(__xludf.DUMMYFUNCTION("MAX(VALUE(IF(REGEXMATCH($F29, "" ""), LEFT($F29, (FIND("" "", $F29, 1) - 1)), 0)), VALUE(IF(REGEXMATCH($H29, "" ""), LEFT($H29, (FIND("" "", $H29, 1) - 1)), 0)), VALUE(IF(REGEXMATCH($J29, "" ""), LEFT($J29, (FIND("" "", $J29, 1) - 1)), 0)), VALUE(IF(REGEX"&"MATCH($L29, "" ""), LEFT($L29, (FIND("" "", $L29, 1) - 1)), 0)), VALUE(IF(REGEXMATCH($N29, "" ""), LEFT($N29, (FIND("" "", $N29, 1) - 1)), 0)), VALUE(IF(REGEXMATCH($P29, "" ""), LEFT($P29, (FIND("" "", $P29, 1) - 1)), 0)), VALUE(IF(REGEXMATCH($R29, "" "")"&", LEFT($R29, (FIND("" "", $R29, 1) - 1)), 0)), VALUE(IF(REGEXMATCH($T29, "" ""), LEFT($T29, (FIND("" "", $T29, 1) - 1)), 0)), VALUE(IF(REGEXMATCH($V29, "" ""), LEFT($V29, (FIND("" "", $V29, 1) - 1)), 0)))"),0.0) -> 0 | X29: =$W29*1.25 -> 0
A30: 30 | B30: 160118733030 | C30: JANAKIRAM SHARMA KASHIGARI | D30: YES | E30: Accenture (Adv ASE) | F30: 6.5 LPA | G30: Capillary Technologies | H30: 6 LPA | I30: LTI (Level 3) | J30: 8 LPA | K30: Cognizant GenC Elevate | L30: 4 LPA | M30: Frugal Testing | N30: 5 LPA | O30: Infosys (SE) | P30: 3.6 LPA | Q30: Nutanix (Internship) | R30: 50k | W30: =IFERROR(__xludf.DUMMYFUNCTION("MAX(VALUE(IF(REGEXMATCH($F30, "" ""), LEFT($F30, (FIND("" "", $F30, 1) - 1)), 0)), VALUE(IF(REGEXMATCH($H30, "" ""), LEFT($H30, (FIND("" "", $H30, 1) - 1)), 0)), VALUE(IF(REGEXMATCH($J30, "" ""), LEFT($J30, (FIND("" "", $J30, 1) - 1)), 0)), VALUE(IF(REGEX"&"MATCH($L30, "" ""), LEFT($L30, (FIND("" "", $L30, 1) - 1)), 0)), VALUE(IF(REGEXMATCH($N30, "" ""), LEFT($N30, (FIND("" "", $N30, 1) - 1)), 0)), VALUE(IF(REGEXMATCH($P30, "" ""), LEFT($P30, (FIND("" "", $P30, 1) - 1)), 0)), VALUE(IF(REGEXMATCH($R30, "" "")"&", LEFT($R30, (FIND("" "", $R30, 1) - 1)), 0)), VALUE(IF(REGEXMATCH($T30, "" ""), LEFT($T30, (FIND("" "", $T30, 1) - 1)), 0)), VALUE(IF(REGEXMATCH($V30, "" ""), LEFT($V30, (FIND("" "", $V30, 1) - 1)), 0)))"),8.0) -> 8 | X30: =$W30*1.25 -> 10
A31: 31 | B31: 160118733031 | C31: Nelavelli Kedarnath Rishit | D31: YES | E31: Accenture (ASE) | F31: 4.5 LPA | G31: Next Education | H31: 6 LPA | W31: =IFERROR(__xludf.DUMMYFUNCTION("MAX(VALUE(IF(REGEXMATCH($F31, "" ""), LEFT($F31, (FIND("" "", $F31, 1) - 1)), 0)), VALUE(IF(REGEXMATCH($H31, "" ""), LEFT($H31, (FIND("" "", $H31, 1) - 1)), 0)), VALUE(IF(REGEXMATCH($J31, "" ""), LEFT($J31, (FIND("" "", $J31, 1) - 1)), 0)), VALUE(IF(REGEX"&"MATCH($L31, "" ""), LEFT($L31, (FIND("" "", $L31, 1) - 1)), 0)), VALUE(IF(REGEXMATCH($N31, "" ""), LEFT($N31, (FIND("" "", $N31, 1) - 1)), 0)), VALUE(IF(REGEXMATCH($P31, "" ""), LEFT($P31, (FIND("" "", $P31, 1) - 1)), 0)), VALUE(IF(REGEXMATCH($R31, "" "")"&", LEFT($R31, (FIND("" "", $R31, 1) - 1)), 0)), VALUE(IF(REGEXMATCH($T31, "" ""), LEFT($T31, (FIND("" "", $T31, 1) - 1)), 0)), VALUE(IF(REGEXMATCH($V31, "" ""), LEFT($V31, (FIND("" "", $V31, 1) - 1)), 0)))"),6.0) -> 6 | X31: =$W31*1.25 -> 7.5
A32: 32 | B32: 160118733032 | C32: Narsimha Sadula | D32: YES | E32: Micron (EPS) | F32: 8.1 LPA | G32: Infosys (SE) | H32: 3.6 LPA | I32: Darwin Box (Internship) | J32: 25K | W32: =IFERROR(__xludf.DUMMYFUNCTION("MAX(VALUE(IF(REGEXMATCH($F32, "" ""), LEFT($F32, (FIND("" "", $F32, 1) - 1)), 0)), VALUE(IF(REGEXMATCH($H32, "" ""), LEFT($H32, (FIND("" "", $H32, 1) - 1)), 0)), VALUE(IF(REGEXMATCH($J32, "" ""), LEFT($J32, (FIND("" "", $J32, 1) - 1)), 0)), VALUE(IF(REGEX"&"MATCH($L32, "" ""), LEFT($L32, (FIND("" "", $L32, 1) - 1)), 0)), VALUE(IF(REGEXMATCH($N32, "" ""), LEFT($N32, (FIND("" "", $N32, 1) - 1)), 0)), VALUE(IF(REGEXMATCH($P32, "" ""), LEFT($P32, (FIND("" "", $P32, 1) - 1)), 0)), VALUE(IF(REGEXMATCH($R32, "" "")"&", LEFT($R32, (FIND("" "", $R32, 1) - 1)), 0)), VALUE(IF(REGEXMATCH($T32, "" ""), LEFT($T32, (FIND("" "", $T32, 1) - 1)), 0)), VALUE(IF(REGEXMATCH($V32, "" ""), LEFT($V32, (FIND("" "", $V32, 1) - 1)), 0)))"),8.1) -> 8.1 | X32: =$W32*1.25 -> 10.125
A33: 33 | B33: 160118733033 | C33: BEJGAM NITHIN SAI | D33: YES | E33: Accelerize 360 | F33: 7 LPA | G33: Darwin Box (Internship) | H33: 25K | W33: =IFERROR(__xludf.DUMMYFUNCTION("MAX(VALUE(IF(REGEXMATCH($F33, "" ""), LEFT($F33, (FIND("" "", $F33, 1) - 1)), 0)), VALUE(IF(REGEXMATCH($H33, "" ""), LEFT($H33, (FIND("" "", $H33, 1) - 1)), 0)), VALUE(IF(REGEXMATCH($J33, "" ""), LEFT($J33, (FIND("" "", $J33, 1) - 1)), 0)), VALUE(IF(REGEX"&"MATCH($L33, "" ""), LEFT($L33, (FIND("" "", $L33, 1) - 1)), 0)), VALUE(IF(REGEXMATCH($N33, "" ""), LEFT($N33, (FIND("" "", $N33, 1) - 1)), 0)), VALUE(IF(REGEXMATCH($P33, "" ""), LEFT($P33, (FIND("" "", $P33, 1) - 1)), 0)), VALUE(IF(REGEXMATCH($R33, "" "")"&", LEFT($R33, (FIND("" "", $R33, 1) - 1)), 0)), VALUE(IF(REGEXMATCH($T33, "" ""), LEFT($T33, (FIND("" "", $T33, 1) - 1)), 0)), VALUE(IF(REGEXMATCH($V33, "" ""), LEFT($V33, (FIND("" "", $V33, 1) - 1)), 0)))"),7.0) -> 7 | X33: =$W33*1.25 -> 8.75
A34: 34 | B34: 160118733034 | C34: Phani Varma Gadiraju | D34: YES | E34: Micron (ETD) | F34: 8.1 LPA | W34: =IFERROR(__xludf.DUMMYFUNCTION("MAX(VALUE(IF(REGEXMATCH($F34, "" ""), LEFT($F34, (FIND("" "", $F34, 1) - 1)), 0)), VALUE(IF(REGEXMATCH($H34, "" ""), LEFT($H34, (FIND("" "", $H34, 1) - 1)), 0)), VALUE(IF(REGEXMATCH($J34, "" ""), LEFT($J34, (FIND("" "", $J34, 1) - 1)), 0)), VALUE(IF(REGEX"&"MATCH($L34, "" ""), LEFT($L34, (FIND("" "", $L34, 1) - 1)), 0)), VALUE(IF(REGEXMATCH($N34, "" ""), LEFT($N34, (FIND("" "", $N34, 1) - 1)), 0)), VALUE(IF(REGEXMATCH($P34, "" ""), LEFT($P34, (FIND("" "", $P34, 1) - 1)), 0)), VALUE(IF(REGEXMATCH($R34, "" "")"&", LEFT($R34, (FIND("" "", $R34, 1) - 1)), 0)), VALUE(IF(REGEXMATCH($T34, "" ""), LEFT($T34, (FIND("" "", $T34, 1) - 1)), 0)), VALUE(IF(REGEXMATCH($V34, "" ""), LEFT($V34, (FIND("" "", $V34, 1) - 1)), 0)))"),8.1) -> 8.1 | X34: =$W34*1.25 -> 10.125
A35: 35 | B35: 160118733035 | C35: Mudavath prakash | E35: DBS | F35: 8.5 LPA | W35: =IFERROR(__xludf.DUMMYFUNCTION("MAX(VALUE(IF(REGEXMATCH($F35, "" ""), LEFT($F35, (FIND("" "", $F35, 1) - 1)), 0)), VALUE(IF(REGEXMATCH($H35, "" ""), LEFT($H35, (FIND("" "", $H35, 1) - 1)), 0)), VALUE(IF(REGEXMATCH($J35, "" ""), LEFT($J35, (FIND("" "", $J35, 1) - 1)), 0)), VALUE(IF(REGEX"&"MATCH($L35, "" ""), LEFT($L35, (FIND("" "", $L35, 1) - 1)), 0)), VALUE(IF(REGEXMATCH($N35, "" ""), LEFT($N35, (FIND("" "", $N35, 1) - 1)), 0)), VALUE(IF(REGEXMATCH($P35, "" ""), LEFT($P35, (FIND("" "", $P35, 1) - 1)), 0)), VALUE(IF(REGEXMATCH($R35, "" "")"&", LEFT($R35, (FIND("" "", $R35, 1) - 1)), 0)), VALUE(IF(REGEXMATCH($T35, "" ""), LEFT($T35, (FIND("" "", $T35, 1) - 1)), 0)), VALUE(IF(REGEXMATCH($V35, "" ""), LEFT($V35, (FIND("" "", $V35, 1) - 1)), 0)))"),8.5) -> 8.5 | X35: =$W35*1.25 -> 10.625
A36: 36 | B36: 160118733036 | C36: Pranav vinod kaple | D36: YES | E36: Cognizant GenC Next | F36: 6.75 LPA | W36: =IFERROR(__xludf.DUMMYFUNCTION("MAX(VALUE(IF(REGEXMATCH($F36, "" ""), LEFT($F36, (FIND("" "", $F36, 1) - 1)), 0)), VALUE(IF(REGEXMATCH($H36, "" ""), LEFT($H36, (FIND("" "", $H36, 1) - 1)), 0)), VALUE(IF(REGEXMATCH($J36, "" ""), LEFT($J36, (FIND("" "", $J36, 1) - 1)), 0)), VALUE(IF(REGEX"&"MATCH($L36, "" ""), LEFT($L36, (FIND("" "", $L36, 1) - 1)), 0)), VALUE(IF(REGEXMATCH($N36, "" ""), LEFT($N36, (FIND("" "", $N36, 1) - 1)), 0)), VALUE(IF(REGEXMATCH($P36, "" ""), LEFT($P36, (FIND("" "", $P36, 1) - 1)), 0)), VALUE(IF(REGEXMATCH($R36, "" "")"&", LEFT($R36, (FIND("" "", $R36, 1) - 1)), 0)), VALUE(IF(REGEXMATCH($T36, "" ""), LEFT($T36, (FIND("" "", $T36, 1) - 1)), 0)), VALUE(IF(REGEXMATCH($V36, "" ""), LEFT($V36, (FIND("" "", $V36, 1) - 1)), 0)))"),6.75) -> 6.75 | X36: =$W36*1.25 -> 8.4375
A37: 37 | B37: 160118733037 | C37: Dendi Praneeth Reddy | W37: =IFERROR(__xludf.DUMMYFUNCTION("MAX(VALUE(IF(REGEXMATCH($F37, "" ""), LEFT($F37, (FIND("" "", $F37, 1) - 1)), 0)), VALUE(IF(REGEXMATCH($H37, "" ""), LEFT($H37, (FIND("" "", $H37, 1) - 1)), 0)), VALUE(IF(REGEXMATCH($J37, "" ""), LEFT($J37, (FIND("" "", $J37, 1) - 1)), 0)), VALUE(IF(REGEX"&"MATCH($L37, "" ""), LEFT($L37, (FIND("" "", $L37, 1) - 1)), 0)), VALUE(IF(REGEXMATCH($N37, "" ""), LEFT($N37, (FIND("" "", $N37, 1) - 1)), 0)), VALUE(IF(REGEXMATCH($P37, "" ""), LEFT($P37, (FIND("" "", $P37, 1) - 1)), 0)), VALUE(IF(REGEXMATCH($R37, "" "")"&", LEFT($R37, (FIND("" "", $R37, 1) - 1)), 0)), VALUE(IF(REGEXMATCH($T37, "" ""), LEFT($T37, (FIND("" "", $T37, 1) - 1)), 0)), VALUE(IF(REGEXMATCH($V37, "" ""), LEFT($V37, (FIND("" "", $V37, 1) - 1)), 0)))"),0.0) -> 0 | X37: =$W37*1.25 -> 0
A38: 38 | B38: 160118733038 | C38: Rama Krishna Parjanya Varanasi | D38: YES | E38: JPMC (PPO) | F38: 14 LPA | W38: =IFERROR(__xludf.DUMMYFUNCTION("MAX(VALUE(IF(REGEXMATCH($F38, "" ""), LEFT($F38, (FIND("" "", $F38, 1) - 1)), 0)), VALUE(IF(REGEXMATCH($H38, "" ""), LEFT($H38, (FIND("" "", $H38, 1) - 1)), 0)), VALUE(IF(REGEXMATCH($J38, "" ""), LEFT($J38, (FIND("" "", $J38, 1) - 1)), 0)), VALUE(IF(REGEX"&"MATCH($L38, "" ""), LEFT($L38, (FIND("" "", $L38, 1) - 1)), 0)), VALUE(IF(REGEXMATCH($N38, "" ""), LEFT($N38, (FIND("" "", $N38, 1) - 1)), 0)), VALUE(IF(REGEXMATCH($P38, "" ""), LEFT($P38, (FIND("" "", $P38, 1) - 1)), 0)), VALUE(IF(REGEXMATCH($R38, "" "")"&", LEFT($R38, (FIND("" "", $R38, 1) - 1)), 0)), VALUE(IF(REGEXMATCH($T38, "" ""), LEFT($T38, (FIND("" "", $T38, 1) - 1)), 0)), VALUE(IF(REGEXMATCH($V38, "" ""), LEFT($V38, (FIND("" "", $V38, 1) - 1)), 0)))"),14.0) -> 14 | X38: =$W38*1.25 -> 17.5
A39: 39 | B39: 160118733039 | C39: Rama Krishna Reddy Rela | D39: YES | E39: Cognizant GenC | F39: 4 LPA | G39: Merilytics | H39: 6.5 LPA | I39: Wipro | J39: 3.5 LPA | W39: =IFERROR(__xludf.DUMMYFUNCTION("MAX(VALUE(IF(REGEXMATCH($F39, "" ""), LEFT($F39, (FIND("" "", $F39, 1) - 1)), 0)), VALUE(IF(REGEXMATCH($H39, "" ""), LEFT($H39, (FIND("" "", $H39, 1) - 1)), 0)), VALUE(IF(REGEXMATCH($J39, "" ""), LEFT($J39, (FIND("" "", $J39, 1) - 1)), 0)), VALUE(IF(REGEX"&"MATCH($L39, "" ""), LEFT($L39, (FIND("" "", $L39, 1) - 1)), 0)), VALUE(IF(REGEXMATCH($N39, "" ""), LEFT($N39, (FIND("" "", $N39, 1) - 1)), 0)), VALUE(IF(REGEXMATCH($P39, "" ""), LEFT($P39, (FIND("" "", $P39, 1) - 1)), 0)), VALUE(IF(REGEXMATCH($R39, "" "")"&", LEFT($R39, (FIND("" "", $R39, 1) - 1)), 0)), VALUE(IF(REGEXMATCH($T39, "" ""), LEFT($T39, (FIND("" "", $T39, 1) - 1)), 0)), VALUE(IF(REGEXMATCH($V39, "" ""), LEFT($V39, (FIND("" "", $V39, 1) - 1)), 0)))"),6.5) -> 6.5 | X39: =$W39*1.25 -> 8.125
A40: 41 | B40: 160118733041 | C40: S Revanth Reddy | D40: YES | E40: Cognizant GenC Elevate | F40: 4 LPA | G40: Wipro | H40: 3.5 LPA | I40: Infosys (SE) | J40: 3.6 LPA | W40: =IFERROR(__xludf.DUMMYFUNCTION("MAX(VALUE(IF(REGEXMATCH($F40, "" ""), LEFT($F40, (FIND("" "", $F40, 1) - 1)), 0)), VALUE(IF(REGEXMATCH($H40, "" ""), LEFT($H40, (FIND("" "", $H40, 1) - 1)), 0)), VALUE(IF(REGEXMATCH($J40, "" ""), LEFT($J40, (FIND("" "", $J40, 1) - 1)), 0)), VALUE(IF(REGEX"&"MATCH($L40, "" ""), LEFT($L40, (FIND("" "", $L40, 1) - 1)), 0)), VALUE(IF(REGEXMATCH($N40, "" ""), LEFT($N40, (FIND("" "", $N40, 1) - 1)), 0)), VALUE(IF(REGEXMATCH($P40, "" ""), LEFT($P40, (FIND("" "", $P40, 1) - 1)), 0)), VALUE(IF(REGEXMATCH($R40, "" "")"&", LEFT($R40, (FIND("" "", $R40, 1) - 1)), 0)), VALUE(IF(REGEXMATCH($T40, "" ""), LEFT($T40, (FIND("" "", $T40, 1) - 1)), 0)), VALUE(IF(REGEXMATCH($V40, "" ""), LEFT($V40, (FIND("" "", $V40, 1) - 1)), 0)))"),4.0) -> 4 | X40: =$W40*1.25 -> 5
...

Sheet CSE2
A1: varun | B1: Roll Number | C1: Name | D1: 6M Internship | E1: First Company Placed | F1: Package | G1: Second Company Placed | H1: Package | I1: Third Company Placed | J1: Package | K1: Fourth Company Placed | L1: Package | M1: Fifth Company Placed | N1: Package | O1: Sixth Company Placed | P1: Package | Q1: Seventh Company Placed | R1: Package | S1: Eighth Company Placed | T1: Package | U1: Ninth Company Placed | V1: Package | W1: Highest Package | X1: Eligibility
A2: 1 | B2: 160118733061 | C2: Akhila Patlolla | E2: Wipro | F2: 3.5 LPA | G2: Mu Sigma | H2: 3.5 LPA | W2: =IFERROR(__xludf.DUMMYFUNCTION("MAX(VALUE(IF(REGEXMATCH($F2, "" ""), LEFT($F2, (FIND("" "", $F2, 1) - 1)), 0)), VALUE(IF(REGEXMATCH($H2, "" ""), LEFT($H2, (FIND("" "", $H2, 1) - 1)), 0)), VALUE(IF(REGEXMATCH($J2, "" ""), LEFT($J2, (FIND("" "", $J2, 1) - 1)), 0)), VALUE(IF(REGEXMATCH($L2"&", "" ""), LEFT($L2, (FIND("" "", $L2, 1) - 1)), 0)), VALUE(IF(REGEXMATCH($N2, "" ""), LEFT($N2, (FIND("" "", $N2, 1) - 1)), 0)), VALUE(IF(REGEXMATCH($P2, "" ""), LEFT($P2, (FIND("" "", $P2, 1) - 1)), 0)), VALUE(IF(REGEXMATCH($R2, "" ""), LEFT($R2, (FIND("&""" "", $R2, 1) - 1)), 0)), VALUE(IF(REGEXMATCH($T2, "" ""), LEFT($T2, (FIND("" "", $T2, 1) - 1)), 0)), VALUE(IF(REGEXMATCH($V2, "" ""), LEFT($V2, (FIND("" "", $V2, 1) - 1)), 0)))"),3.5) -> 3.5 | X2: =$W2*1.25 -> 4.375
A3: 2 | B3: 160118733062 | C3: Bhavishya Agarwal | D3: YES | E3: SalesForce | F3: 19.65 LPA | G3: Infosys (SE) | H3: 3.6 LPA | I3: Caspian Debt (Internship) | J3: 15K | W3: =IFERROR(__xludf.DUMMYFUNCTION("MAX(VALUE(IF(REGEXMATCH($F3, "" ""), LEFT($F3, (FIND("" "", $F3, 1) - 1)), 0)), VALUE(IF(REGEXMATCH($H3, "" ""), LEFT($H3, (FIND("" "", $H3, 1) - 1)), 0)), VALUE(IF(REGEXMATCH($J3, "" ""), LEFT($J3, (FIND("" "", $J3, 1) - 1)), 0)), VALUE(IF(REGEXMATCH($L3"&", "" ""), LEFT($L3, (FIND("" "", $L3, 1) - 1)), 0)), VALUE(IF(REGEXMATCH($N3, "" ""), LEFT($N3, (FIND("" "", $N3, 1) - 1)), 0)), VALUE(IF(REGEXMATCH($P3, "" ""), LEFT($P3, (FIND("" "", $P3, 1) - 1)), 0)), VALUE(IF(REGEXMATCH($R3, "" ""), LEFT($R3, (FIND("&""" "", $R3, 1) - 1)), 0)), VALUE(IF(REGEXMATCH($T3, "" ""), LEFT($T3, (FIND("" "", $T3, 1) - 1)), 0)), VALUE(IF(REGEXMATCH($V3, "" ""), LEFT($V3, (FIND("" "", $V3, 1) - 1)), 0)))"),19.65) -> 19.65 | X3: =$W3*1.25 -> 24.5625
A4: 3 | B4: 160118733063 | C4: Harshitha Dendeti | D4: YES | E4: Cognizant GenC Elevate | F4: 4 LPA | W4: =IFERROR(__xludf.DUMMYFUNCTION("MAX(VALUE(IF(REGEXMATCH($F4, "" ""), LEFT($F4, (FIND("" "", $F4, 1) - 1)), 0)), VALUE(IF(REGEXMATCH($H4, "" ""), LEFT($H4, (FIND("" "", $H4, 1) - 1)), 0)), VALUE(IF(REGEXMATCH($J4, "" ""), LEFT($J4, (FIND("" "", $J4, 1) - 1)), 0)), VALUE(IF(REGEXMATCH($L4"&", "" ""), LEFT($L4, (FIND("" "", $L4, 1) - 1)), 0)), VALUE(IF(REGEXMATCH($N4, "" ""), LEFT($N4, (FIND("" "", $N4, 1) - 1)), 0)), VALUE(IF(REGEXMATCH($P4, "" ""), LEFT($P4, (FIND("" "", $P4, 1) - 1)), 0)), VALUE(IF(REGEXMATCH($R4, "" ""), LEFT($R4, (FIND("&""" "", $R4, 1) - 1)), 0)), VALUE(IF(REGEXMATCH($T4, "" ""), LEFT($T4, (FIND("" "", $T4, 1) - 1)), 0)), VALUE(IF(REGEXMATCH($V4, "" ""), LEFT($V4, (FIND("" "", $V4, 1) - 1)), 0)))"),4.0) -> 4 | X4: =$W4*1.25 -> 5
A5: 4 | B5: 160118733064 | C5: Jahnavi Jonnalagadda | E5: Advance Auto Parts (PPO) | F5: 9 LPA | G5: F5 Inc | H5: 23 LPA | W5: =IFERROR(__xludf.DUMMYFUNCTION("MAX(VALUE(IF(REGEXMATCH($F5, "" ""), LEFT($F5, (FIND("" "", $F5, 1) - 1)), 0)), VALUE(IF(REGEXMATCH($H5, "" ""), LEFT($H5, (FIND("" "", $H5, 1) - 1)), 0)), VALUE(IF(REGEXMATCH($J5, "" ""), LEFT($J5, (FIND("" "", $J5, 1) - 1)), 0)), VALUE(IF(REGEXMATCH($L5"&", "" ""), LEFT($L5, (FIND("" "", $L5, 1) - 1)), 0)), VALUE(IF(REGEXMATCH($N5, "" ""), LEFT($N5, (FIND("" "", $N5, 1) - 1)), 0)), VALUE(IF(REGEXMATCH($P5, "" ""), LEFT($P5, (FIND("" "", $P5, 1) - 1)), 0)), VALUE(IF(REGEXMATCH($R5, "" ""), LEFT($R5, (FIND("&""" "", $R5, 1) - 1)), 0)), VALUE(IF(REGEXMATCH($T5, "" ""), LEFT($T5, (FIND("" "", $T5, 1) - 1)), 0)), VALUE(IF(REGEXMATCH($V5, "" ""), LEFT($V5, (FIND("" "", $V5, 1) - 1)), 0)))"),23.0) -> 23 | X5: =$W5*1.25 -> 28.75
A6: 5 | B6: 160118733065 | C6: Keerthi Boya | D6: YES | E6: Accenture (ASE) | F6: 4.5 LPA | G6: Wipro | H6: 3.5 LPA | I6: Collins Aerospace (Internship) | J6: 6.25 LPA | K6: Ford Motors | L6: 5.7 LPA | M6: Loyalty Juggernaut Inc | N6: 7 LPA | O6: Head Digital Works | P6: 12 LPA | W6: =IFERROR(__xludf.DUMMYFUNCTION("MAX(VALUE(IF(REGEXMATCH($F6, "" ""), LEFT($F6, (FIND("" "", $F6, 1) - 1)), 0)), VALUE(IF(REGEXMATCH($H6, "" ""), LEFT($H6, (FIND("" "", $H6, 1) - 1)), 0)), VALUE(IF(REGEXMATCH($J6, "" ""), LEFT($J6, (FIND("" "", $J6, 1) - 1)), 0)), VALUE(IF(REGEXMATCH($L6"&", "" ""), LEFT($L6, (FIND("" "", $L6, 1) - 1)), 0)), VALUE(IF(REGEXMATCH($N6, "" ""), LEFT($N6, (FIND("" "", $N6, 1) - 1)), 0)), VALUE(IF(REGEXMATCH($P6, "" ""), LEFT($P6, (FIND("" "", $P6, 1) - 1)), 0)), VALUE(IF(REGEXMATCH($R6, "" ""), LEFT($R6, (FIND("&""" "", $R6, 1) - 1)), 0)), VALUE(IF(REGEXMATCH($T6, "" ""), LEFT($T6, (FIND("" "", $T6, 1) - 1)), 0)), VALUE(IF(REGEXMATCH($V6, "" ""), LEFT($V6, (FIND("" "", $V6, 1) - 1)), 0)))"),12.0) -> 12 | X6: =$W6*1.25 -> 15
A7: 6 | B7: 160118733066 | C7: Kini Sanjula Dasari | E7: Deloitte (Consulting) | F7: 7.6 LPA | G7: Barclays | H7: 12.73 LPA | W7: =IFERROR(__xludf.DUMMYFUNCTION("MAX(VALUE(IF(REGEXMATCH($F7, "" ""), LEFT($F7, (FIND("" "", $F7, 1) - 1)), 0)), VALUE(IF(REGEXMATCH($H7, "" ""), LEFT($H7, (FIND("" "", $H7, 1) - 1)), 0)), VALUE(IF(REGEXMATCH($J7, "" ""), LEFT($J7, (FIND("" "", $J7, 1) - 1)), 0)), VALUE(IF(REGEXMATCH($L7"&", "" ""), LEFT($L7, (FIND("" "", $L7, 1) - 1)), 0)), VALUE(IF(REGEXMATCH($N7, "" ""), LEFT($N7, (FIND("" "", $N7, 1) - 1)), 0)), VALUE(IF(REGEXMATCH($P7, "" ""), LEFT($P7, (FIND("" "", $P7, 1) - 1)), 0)), VALUE(IF(REGEXMATCH($R7, "" ""), LEFT($R7, (FIND("&""" "", $R7, 1) - 1)), 0)), VALUE(IF(REGEXMATCH($T7, "" ""), LEFT($T7, (FIND("" "", $T7, 1) - 1)), 0)), VALUE(IF(REGEXMATCH($V7, "" ""), LEFT($V7, (FIND("" "", $V7, 1) - 1)), 0)))"),12.73) -> 12.73 | X7: =$W7*1.25 -> 15.9125
A8: 7 | B8: 160118733067 | C8: Komali Beeram | D8: YES | E8: Accelerize 360 | F8: 7 LPA | G8: Cognizant GenC Next | H8: 6.75 LPA | I8: GE Appliances (Internship) | J8: 20K | K8: Advance Auto Parts | L8: 9 LPA | M8: GAP | N8: 9.08 LPA | O8: PegaSystems | P8: 16 LPA | W8: =IFERROR(__xludf.DUMMYFUNCTION("MAX(VALUE(IF(REGEXMATCH($F8, "" ""), LEFT($F8, (FIND("" "", $F8, 1) - 1)), 0)), VALUE(IF(REGEXMATCH($H8, "" ""), LEFT($H8, (FIND("" "", $H8, 1) - 1)), 0)), VALUE(IF(REGEXMATCH($J8, "" ""), LEFT($J8, (FIND("" "", $J8, 1) - 1)), 0)), VALUE(IF(REGEXMATCH($L8"&", "" ""), LEFT($L8, (FIND("" "", $L8, 1) - 1)), 0)), VALUE(IF(REGEXMATCH($N8, "" ""), LEFT($N8, (FIND("" "", $N8, 1) - 1)), 0)), VALUE(IF(REGEXMATCH($P8, "" ""), LEFT($P8, (FIND("" "", $P8, 1) - 1)), 0)), VALUE(IF(REGEXMATCH($R8, "" ""), LEFT($R8, (FIND("&""" "", $R8, 1) - 1)), 0)), VALUE(IF(REGEXMATCH($T8, "" ""), LEFT($T8, (FIND("" "", $T8, 1) - 1)), 0)), VALUE(IF(REGEXMATCH($V8, "" ""), LEFT($V8, (FIND("" "", $V8, 1) - 1)), 0)))"),16.0) -> 16 | X8: =$W8*1.25 -> 20
A9: 8 | B9: 160118733068 | C9: Manasa Motepalli | D9: YES | E9: Accenture (ASE) | F9: 4.5 LPA | G9: Cognizant GenC | H9: 4 LPA | I9: Capgemini (Analyst) | J9: 4 LPA | K9: Wipro | L9: 3.5 LPA | W9: =IFERROR(__xludf.DUMMYFUNCTION("MAX(VALUE(IF(REGEXMATCH($F9, "" ""), LEFT($F9, (FIND("" "", $F9, 1) - 1)), 0)), VALUE(IF(REGEXMATCH($H9, "" ""), LEFT($H9, (FIND("" "", $H9, 1) - 1)), 0)), VALUE(IF(REGEXMATCH($J9, "" ""), LEFT($J9, (FIND("" "", $J9, 1) - 1)), 0)), VALUE(IF(REGEXMATCH($L9"&", "" ""), LEFT($L9, (FIND("" "", $L9, 1) - 1)), 0)), VALUE(IF(REGEXMATCH($N9, "" ""), LEFT($N9, (FIND("" "", $N9, 1) - 1)), 0)), VALUE(IF(REGEXMATCH($P9, "" ""), LEFT($P9, (FIND("" "", $P9, 1) - 1)), 0)), VALUE(IF(REGEXMATCH($R9, "" ""), LEFT($R9, (FIND("&""" "", $R9, 1) - 1)), 0)), VALUE(IF(REGEXMATCH($T9, "" ""), LEFT($T9, (FIND("" "", $T9, 1) - 1)), 0)), VALUE(IF(REGEXMATCH($V9, "" ""), LEFT($V9, (FIND("" "", $V9, 1) - 1)), 0)))"),4.5) -> 4.5 | X9: =$W9*1.25 -> 5.625
A10: 9 | B10: 160118733069 | C10: Rizmi Nawaz Sowdhagar | E10: Wipro | F10: 3.5 LPA | G10: HCL | H10: 4.5 LPA | W10: =IFERROR(__xludf.DUMMYFUNCTION("MAX(VALUE(IF(REGEXMATCH($F10, "" ""), LEFT($F10, (FIND("" "", $F10, 1) - 1)), 0)), VALUE(IF(REGEXMATCH($H10, "" ""), LEFT($H10, (FIND("" "", $H10, 1) - 1)), 0)), VALUE(IF(REGEXMATCH($J10, "" ""), LEFT($J10, (FIND("" "", $J10, 1) - 1)), 0)), VALUE(IF(REGEX"&"MATCH($L10, "" ""), LEFT($L10, (FIND("" "", $L10, 1) - 1)), 0)), VALUE(IF(REGEXMATCH($N10, "" ""), LEFT($N10, (FIND("" "", $N10, 1) - 1)), 0)), VALUE(IF(REGEXMATCH($P10, "" ""), LEFT($P10, (FIND("" "", $P10, 1) - 1)), 0)), VALUE(IF(REGEXMATCH($R10, "" "")"&", LEFT($R10, (FIND("" "", $R10, 1) - 1)), 0)), VALUE(IF(REGEXMATCH($T10, "" ""), LEFT($T10, (FIND("" "", $T10, 1) - 1)), 0)), VALUE(IF(REGEXMATCH($V10, "" ""), LEFT($V10, (FIND("" "", $V10, 1) - 1)), 0)))"),4.5) -> 4.5 | X10: =$W10*1.25 -> 5.625
A11: 10 | B11: 160118733070 | C11: Neha Bhupathi | D11: YES | E11: Collins Aerospace (Internship) | F11: 15k | W11: =IFERROR(__xludf.DUMMYFUNCTION("MAX(VALUE(IF(REGEXMATCH($F11, "" ""), LEFT($F11, (FIND("" "", $F11, 1) - 1)), 0)), VALUE(IF(REGEXMATCH($H11, "" ""), LEFT($H11, (FIND("" "", $H11, 1) - 1)), 0)), VALUE(IF(REGEXMATCH($J11, "" ""), LEFT($J11, (FIND("" "", $J11, 1) - 1)), 0)), VALUE(IF(REGEX"&"MATCH($L11, "" ""), LEFT($L11, (FIND("" "", $L11, 1) - 1)), 0)), VALUE(IF(REGEXMATCH($N11, "" ""), LEFT($N11, (FIND("" "", $N11, 1) - 1)), 0)), VALUE(IF(REGEXMATCH($P11, "" ""), LEFT($P11, (FIND("" "", $P11, 1) - 1)), 0)), VALUE(IF(REGEXMATCH($R11, "" "")"&", LEFT($R11, (FIND("" "", $R11, 1) - 1)), 0)), VALUE(IF(REGEXMATCH($T11, "" ""), LEFT($T11, (FIND("" "", $T11, 1) - 1)), 0)), VALUE(IF(REGEXMATCH($V11, "" ""), LEFT($V11, (FIND("" "", $V11, 1) - 1)), 0)))"),0.0) -> 0 | X11: =$W11*1.25 -> 0
A12: 11 | B12: 160118733071 | C12: Nishitha Garlapati | D12: YES | E12: JPMC (PPO) | F12: 14 LPA | W12: =IFERROR(__xludf.DUMMYFUNCTION("MAX(VALUE(IF(REGEXMATCH($F12, "" ""), LEFT($F12, (FIND("" "", $F12, 1) - 1)), 0)), VALUE(IF(REGEXMATCH($H12, "" ""), LEFT($H12, (FIND("" "", $H12, 1) - 1)), 0)), VALUE(IF(REGEXMATCH($J12, "" ""), LEFT($J12, (FIND("" "", $J12, 1) - 1)), 0)), VALUE(IF(REGEX"&"MATCH($L12, "" ""), LEFT($L12, (FIND("" "", $L12, 1) - 1)), 0)), VALUE(IF(REGEXMATCH($N12, "" ""), LEFT($N12, (FIND("" "", $N12, 1) - 1)), 0)), VALUE(IF(REGEXMATCH($P12, "" ""), LEFT($P12, (FIND("" "", $P12, 1) - 1)), 0)), VALUE(IF(REGEXMATCH($R12, "" "")"&", LEFT($R12, (FIND("" "", $R12, 1) - 1)), 0)), VALUE(IF(REGEXMATCH($T12, "" ""), LEFT($T12, (FIND("" "", $T12, 1) - 1)), 0)), VALUE(IF(REGEXMATCH($V12, "" ""), LEFT($V12, (FIND("" "", $V12, 1) - 1)), 0)))"),14.0) -> 14 | X12: =$W12*1.25 -> 17.5
A13: 12 | B13: 160118733072 | C13: Niveditha Kalva | D13: YES | E13: Micron (IT Operations) | F13: 8.1 LPA | W13: =IFERROR(__xludf.DUMMYFUNCTION("MAX(VALUE(IF(REGEXMATCH($F13, "" ""), LEFT($F13, (FIND("" "", $F13, 1) - 1)), 0)), VALUE(IF(REGEXMATCH($H13, "" ""), LEFT($H13, (FIND("" "", $H13, 1) - 1)), 0)), VALUE(IF(REGEXMATCH($J13, "" ""), LEFT($J13, (FIND("" "", $J13, 1) - 1)), 0)), VALUE(IF(REGEX"&"MATCH($L13, "" ""), LEFT($L13, (FIND("" "", $L13, 1) - 1)), 0)), VALUE(IF(REGEXMATCH($N13, "" ""), LEFT($N13, (FIND("" "", $N13, 1) - 1)), 0)), VALUE(IF(REGEXMATCH($P13, "" ""), LEFT($P13, (FIND("" "", $P13, 1) - 1)), 0)), VALUE(IF(REGEXMATCH($R13, "" "")"&", LEFT($R13, (FIND("" "", $R13, 1) - 1)), 0)), VALUE(IF(REGEXMATCH($T13, "" ""), LEFT($T13, (FIND("" "", $T13, 1) - 1)), 0)), VALUE(IF(REGEXMATCH($V13, "" ""), LEFT($V13, (FIND("" "", $V13, 1) - 1)), 0)))"),8.1) -> 8.1 | X13: =$W13*1.25 -> 10.125
A14: 13 | B14: 160118733073 | C14: Pallavi Maragari | D14: YES | E14: ServiceNow | F14: 25 LPA | W14: =IFERROR(__xludf.DUMMYFUNCTION("MAX(VALUE(IF(REGEXMATCH($F14, "" ""), LEFT($F14, (FIND("" "", $F14, 1) - 1)), 0)), VALUE(IF(REGEXMATCH($H14, "" ""), LEFT($H14, (FIND("" "", $H14, 1) - 1)), 0)), VALUE(IF(REGEXMATCH($J14, "" ""), LEFT($J14, (FIND("" "", $J14, 1) - 1)), 0)), VALUE(IF(REGEX"&"MATCH($L14, "" ""), LEFT($L14, (FIND("" "", $L14, 1) - 1)), 0)), VALUE(IF(REGEXMATCH($N14, "" ""), LEFT($N14, (FIND("" "", $N14, 1) - 1)), 0)), VALUE(IF(REGEXMATCH($P14, "" ""), LEFT($P14, (FIND("" "", $P14, 1) - 1)), 0)), VALUE(IF(REGEXMATCH($R14, "" "")"&", LEFT($R14, (FIND("" "", $R14, 1) - 1)), 0)), VALUE(IF(REGEXMATCH($T14, "" ""), LEFT($T14, (FIND("" "", $T14, 1) - 1)), 0)), VALUE(IF(REGEXMATCH($V14, "" ""), LEFT($V14, (FIND("" "", $V14, 1) - 1)), 0)))"),25.0) -> 25 | X14: =$W14*1.25 -> 31.25
